Workbook

Sheet RECAP
B1: ANNEE | C1: =Données!D2 -> Janvier | D1: =Données!D3 -> Février | E1: =Données!D4 -> Mars | F1: =Données!D5 -> Avril | G1: =Données!D6 -> Mai | H1: =Données!D7 -> Juin | I1: =Données!D8 -> Juillet | J1: =Données!D9 -> Août | K1: =Données!D10 -> Septembre | L1: =Données!D11 -> Octobre | M1: =Données!D12 -> Novembre | N1: =Données!D13 -> Décembre
A2: =SUMIFS(MISSIONS!$AH$3:$AH$2094,MISSIONS!$I$3:$I$2094,A$1) -> 0
A3: CA Generé | B3: =SUM(C3:N3) -> 276915 | C3: =SUMIFS(MISSIONS!$J$3:$J$2096,MISSIONS!$I$3:$I$2096,C$1) -> 16154 | D3: =SUMIFS(MISSIONS!$J$3:$J$2096,MISSIONS!$I$3:$I$2096,D$1) -> 13164 | E3: =SUMIFS(MISSIONS!$J$3:$J$2096,MISSIONS!$I$3:$I$2096,E$1) -> 14514 | F3: =SUMIFS(MISSIONS!$J$3:$J$2096,MISSIONS!$I$3:$I$2096,F$1) -> 12498 | G3: =SUMIFS(MISSIONS!$J$3:$J$2096,MISSIONS!$I$3:$I$2096,G$1) -> 14713 | H3: =SUMIFS(MISSIONS!$J$3:$J$2096,MISSIONS!$I$3:$I$2096,H$1) -> 15782 | I3: =SUMIFS(MISSIONS!$J$3:$J$2096,MISSIONS!$I$3:$I$2096,I$1) -> 15464 | J3: =SUMIFS(MISSIONS!$J$3:$J$2096,MISSIONS!$I$3:$I$2096,J$1) -> 13328 | ... N3: =SUMIFS(MISSIONS!$J$3:$J$2096,MISSIONS!$I$3:$I$2096,N$1) -> 41140
A4: CA Total | B4: =SUM(C4:N4) -> 128171 | C4: =SUMIFS(MISSIONS!$L$3:$L$2096,MISSIONS!$I$3:$I$2096,C$1) -> 6881 | D4: =SUMIFS(MISSIONS!$L$3:$L$2096,MISSIONS!$I$3:$I$2096,D$1) -> 6582 | E4: =SUMIFS(MISSIONS!$L$3:$L$2096,MISSIONS!$I$3:$I$2096,E$1) -> 7507 | F4: =SUMIFS(MISSIONS!$L$3:$L$2096,MISSIONS!$I$3:$I$2096,F$1) -> 5893 | G4: =SUMIFS(MISSIONS!$L$3:$L$2096,MISSIONS!$I$3:$I$2096,G$1) -> 7773 | H4: =SUMIFS(MISSIONS!$L$3:$L$2096,MISSIONS!$I$3:$I$2096,H$1) -> 8885 | I4: =SUMIFS(MISSIONS!$L$3:$L$2096,MISSIONS!$I$3:$I$2096,I$1) -> 8232 | J4: =SUMIFS(MISSIONS!$L$3:$L$2096,MISSIONS!$I$3:$I$2096,J$1) -> 6664 | ... N4: =SUMIFS(MISSIONS!$L$3:$L$2096,MISSIONS!$I$3:$I$2096,N$1) -> 20570
A5: CA Payé | B5: =SUM(C5:N5) -> 82739 | C5: =SUMIFS(MISSIONS!$M$3:$M$2096,MISSIONS!$I$3:$I$2096,C$1) -> 6321 | D5: =SUMIFS(MISSIONS!$M$3:$M$2096,MISSIONS!$I$3:$I$2096,D$1) -> 6232 | E5: =SUMIFS(MISSIONS!$M$3:$M$2096,MISSIONS!$I$3:$I$2096,E$1) -> 7507 | F5: =SUMIFS(MISSIONS!$M$3:$M$2096,MISSIONS!$I$3:$I$2096,F$1) -> 5893 | G5: =SUMIFS(MISSIONS!$M$3:$M$2096,MISSIONS!$I$3:$I$2096,G$1) -> 7773 | H5: =SUMIFS(MISSIONS!$M$3:$M$2096,MISSIONS!$I$3:$I$2096,H$1) -> 8885 | I5: =SUMIFS(MISSIONS!$M$3:$M$2096,MISSIONS!$I$3:$I$2096,I$1) -> 8232 | J5: =SUMIFS(MISSIONS!$M$3:$M$2096,MISSIONS!$I$3:$I$2096,J$1) -> 6664 | ... N5: =SUMIFS(MISSIONS!$M$3:$M$2096,MISSIONS!$I$3:$I$2096,N$1) -> 180
A7: Frais
A8: Provision Charges | B8: =SUM(C8:N8) -> 6614.9 | C8: =SUMIFS(MISSIONS!$P$3:$P$2119,MISSIONS!$I$3:$I$2119,C$1) -> 621.8 | D8: =SUMIFS(MISSIONS!$P$3:$P$2119,MISSIONS!$I$3:$I$2119,D$1) -> 621.8 | E8: =SUMIFS(MISSIONS!$P$3:$P$2119,MISSIONS!$I$3:$I$2119,E$1) -> 699.7 | F8: =SUMIFS(MISSIONS!$P$3:$P$2119,MISSIONS!$I$3:$I$2119,F$1) -> 579.4 | G8: =SUMIFS(MISSIONS!$P$3:$P$2119,MISSIONS!$I$3:$I$2119,G$1) -> 693.4 | H8: =SUMIFS(MISSIONS!$P$3:$P$2119,MISSIONS!$I$3:$I$2119,H$1) -> 609.6 | I8: =SUMIFS(MISSIONS!$P$3:$P$2119,MISSIONS!$I$3:$I$2119,I$1) -> 723.2 | J8: =SUMIFS(MISSIONS!$P$3:$P$2119,MISSIONS!$I$3:$I$2119,J$1) -> 666.4 | ... N8: =SUMIFS(MISSIONS!$P$3:$P$2119,MISSIONS!$I$3:$I$2119,N$1) -> 9
A11: Compta Kdekom | B11: =SUM(C11:N11) -> 1104 | C11: 92 | D11: =C11 -> 92 | E11: =D11 -> 92 | F11: =E11 -> 92 | G11: =F11 -> 92 | H11: =G11 -> 92 | I11: =H11 -> 92 | J11: =I11 -> 92 | K11: =J11 -> 92 | ... N11: =M11 -> 92
A12: Dom | B12: =SUM(C12:N12) -> 720 | C12: 60 | D12: =C12 -> 60 | E12: =D12 -> 60 | F12: =E12 -> 60 | G12: =F12 -> 60 | H12: =G12 -> 60 | I12: =H12 -> 60 | J12: =I12 -> 60 | K12: =J12 -> 60 | ... N12: =M12 -> 60
A13: Téléphone | B13: =SUM(C13:N13) -> 108 | C13: 9 | D13: =C13 -> 9 | E13: =D13 -> 9 | F13: =E13 -> 9 | G13: =F13 -> 9 | H13: =G13 -> 9 | I13: =H13 -> 9 | J13: =I13 -> 9 | K13: =J13 -> 9 | ... N13: =M13 -> 9
A14: Quicbooks | B14: =SUM(C14:N14) -> 180 | C14: 15 | D14: =C14 -> 15 | E14: =D14 -> 15 | F14: =E14 -> 15 | G14: =F14 -> 15 | H14: =G14 -> 15 | I14: =H14 -> 15 | J14: =I14 -> 15 | K14: =J14 -> 15 | ... N14: =M14 -> 15
A15: Wize | B15: =SUM(C15:N15) -> 50.4 | C15: 4.2 | D15: =C15 -> 4.2 | E15: =D15 -> 4.2 | F15: =E15 -> 4.2 | G15: =F15 -> 4.2 | H15: =G15 -> 4.2 | I15: =H15 -> 4.2 | J15: =I15 -> 4.2 | K15: =J15 -> 4.2 | ... N15: =M15 -> 4.2
A16: Google | B16: =SUM(C16:N16) -> 90 | C16: 7.5 | D16: =C16 -> 7.5 | E16: =D16 -> 7.5 | F16: =E16 -> 7.5 | G16: =F16 -> 7.5 | H16: =G16 -> 7.5 | I16: =H16 -> 7.5 | J16: =I16 -> 7.5 | K16: =J16 -> 7.5 | ... N16: =M16 -> 7.5
A17: Amazon | B17: =SUM(C17:N17) -> 96 | C17: 8 | D17: =C17 -> 8 | E17: =D17 -> 8 | F17: =E17 -> 8 | G17: =F17 -> 8 | H17: =G17 -> 8 | I17: =H17 -> 8 | J17: =I17 -> 8 | K17: =J17 -> 8 | ... N17: =M17 -> 8
A19: =MISSIONS!AU2 -> Reliquat | B19: =SUM(C19:N19) -> 10873.644 | C19: =SUMIFS(MISSIONS!$AU$3:$AU$2119,MISSIONS!$I$3:$I$2119,C$1) -> 106.62256 | D19: =SUMIFS(MISSIONS!$AU$3:$AU$2119,MISSIONS!$I$3:$I$2119,D$1) -> 105.73256 | E19: =SUMIFS(MISSIONS!$AU$3:$AU$2119,MISSIONS!$I$3:$I$2119,E$1) -> 117.84964 | F19: =SUMIFS(MISSIONS!$AU$3:$AU$2119,MISSIONS!$I$3:$I$2119,F$1) -> 98.670915 | G19: =SUMIFS(MISSIONS!$AU$3:$AU$2119,MISSIONS!$I$3:$I$2119,G$1) -> 949.10359 | H19: =SUMIFS(MISSIONS!$AU$3:$AU$2119,MISSIONS!$I$3:$I$2119,H$1) -> 2811.1024 | I19: =SUMIFS(MISSIONS!$AU$3:$AU$2119,MISSIONS!$I$3:$I$2119,I$1) -> 181.62791 | J19: =SUMIFS(MISSIONS!$AU$3:$AU$2119,MISSIONS!$I$3:$I$2119,J$1) -> 166.72554 | ... N19: =SUMIFS(MISSIONS!$AU$3:$AU$2119,MISSIONS!$I$3:$I$2119,N$1) -> 1.2303
A20: Reste | B20: =SUM(C20:N20) -> 15140.144 | C20: =C8-SUM(C11:C17)+C19 -> 532.72256 | D20: =D8-SUM(D11:D17)+D19 -> 531.83256 | E20: =E8-SUM(E11:E17)+E19 -> 621.84964 | F20: =F8-SUM(F11:F17)+F19 -> 482.37092 | G20: =G8-SUM(G11:G17)+G19 -> 1446.8036 | H20: =H8-SUM(H11:H17)+H19 -> 3225.0024 | I20: =I8-SUM(I11:I17)+I19 -> 709.12791 | J20: =J8-SUM(J11:J17)+J19 -> 637.42554 | ... N20: =N8-SUM(N11:N17)+N19 -> -185.4697
A22: =MISSIONS!S2 -> Ml | B22: =SUM(C22:N22)+O22 -> 2643.9411 | C22: =SUMIFS(MISSIONS!$S$3:$S$2094,MISSIONS!$I$3:$I$2094,C$1) -> 196.7616 | D22: =SUMIFS(MISSIONS!$S$3:$S$2094,MISSIONS!$I$3:$I$2094,D$1) -> 196.7616 | E22: =SUMIFS(MISSIONS!$S$3:$S$2094,MISSIONS!$I$3:$I$2094,E$1) -> 246.5408 | F22: =SUMIFS(MISSIONS!$S$3:$S$2094,MISSIONS!$I$3:$I$2094,F$1) -> 199.1424 | G22: =SUMIFS(MISSIONS!$S$3:$S$2094,MISSIONS!$I$3:$I$2094,G$1) -> 250.1248 | H22: =SUMIFS(MISSIONS!$S$3:$S$2094,MISSIONS!$I$3:$I$2094,H$1) -> 205.6112 | I22: =SUMIFS(MISSIONS!$S$3:$S$2094,MISSIONS!$I$3:$I$2094,I$1) -> 271.4362 | J22: =SUMIFS(MISSIONS!$S$3:$S$2094,MISSIONS!$I$3:$I$2094,J$1) -> 295.281 | ... N22: =SUMIFS(MISSIONS!$S$3:$S$2094,MISSIONS!$I$3:$I$2094,N$1) -> 11.97
A23: =MISSIONS!T2 -> Lt | B23: =SUM(C23:N23)+O23 -> 1441.7463 | C23: =SUMIFS(MISSIONS!$T$3:$T$2094,MISSIONS!$I$3:$I$2094,C$1) -> 152.24832 | D23: =SUMIFS(MISSIONS!$T$3:$T$2094,MISSIONS!$I$3:$I$2094,D$1) -> 152.24832 | E23: =SUMIFS(MISSIONS!$T$3:$T$2094,MISSIONS!$I$3:$I$2094,E$1) -> 402.36736 | F23: =SUMIFS(MISSIONS!$T$3:$T$2094,MISSIONS!$I$3:$I$2094,F$1) -> 132.61056 | G23: =SUMIFS(MISSIONS!$T$3:$T$2094,MISSIONS!$I$3:$I$2094,G$1) -> 132.7296 | H23: =SUMIFS(MISSIONS!$T$3:$T$2094,MISSIONS!$I$3:$I$2094,H$1) -> 132.96768 | I23: =SUMIFS(MISSIONS!$T$3:$T$2094,MISSIONS!$I$3:$I$2094,I$1) -> 149.58864 | J23: =SUMIFS(MISSIONS!$T$3:$T$2094,MISSIONS!$I$3:$I$2094,J$1) -> 186.9858 | ... N23: =SUMIFS(MISSIONS!$T$3:$T$2094,MISSIONS!$I$3:$I$2094,N$1) -> 0
A24: =MISSIONS!Z2 -> Fred | B24: =SUM(C24:N24)+O24 -> 56506.911 | C24: =SUMIFS(MISSIONS!$Z$3:$Z$2094,MISSIONS!$I$3:$I$2094,C$1) -> 5065.006 | D24: =SUMIFS(MISSIONS!$Z$3:$Z$2094,MISSIONS!$I$3:$I$2094,D$1) -> 4990.246 | E24: =SUMIFS(MISSIONS!$Z$3:$Z$2094,MISSIONS!$I$3:$I$2094,E$1) -> 5584.5716 | F24: =SUMIFS(MISSIONS!$Z$3:$Z$2094,MISSIONS!$I$3:$I$2094,F$1) -> 4697.6629 | G24: =SUMIFS(MISSIONS!$Z$3:$Z$2094,MISSIONS!$I$3:$I$2094,G$1) -> 5511.7361 | H24: =SUMIFS(MISSIONS!$Z$3:$Z$2094,MISSIONS!$I$3:$I$2094,H$1) -> 5116.1334 | I24: =SUMIFS(MISSIONS!$Z$3:$Z$2094,MISSIONS!$I$3:$I$2094,I$1) -> 6978.8156 | J24: =SUMIFS(MISSIONS!$Z$3:$Z$2094,MISSIONS!$I$3:$I$2094,J$1) -> 5162.3266 | ... N24: =SUMIFS(MISSIONS!$Z$3:$Z$2094,MISSIONS!$I$3:$I$2094,N$1) -> 95.9634
A25: =MISSIONS!AB2 -> Eric | B25: =SUM(C25:N25)+O25 -> 1593.8936 | C25: =SUMIFS(MISSIONS!$AB$3:$AB$2094,MISSIONS!$I$3:$I$2094,C$1)+C38 -> 13.35 | D25: =SUMIFS(MISSIONS!$AB$3:$AB$2094,MISSIONS!$I$3:$I$2094,D$1)+D38 -> 0 | E25: =SUMIFS(MISSIONS!$AB$3:$AB$2094,MISSIONS!$I$3:$I$2094,E$1)+E38 -> 0 | F25: =SUMIFS(MISSIONS!$AB$3:$AB$2094,MISSIONS!$I$3:$I$2094,F$1)+F38 -> 13.35 | G25: =SUMIFS(MISSIONS!$AB$3:$AB$2094,MISSIONS!$I$3:$I$2094,G$1)+G38 -> 0 | H25: =SUMIFS(MISSIONS!$AB$3:$AB$2094,MISSIONS!$I$3:$I$2094,H$1)+H38 -> 13.35 | I25: =SUMIFS(MISSIONS!$AB$3:$AB$2094,MISSIONS!$I$3:$I$2094,I$1)+I38 -> 0 | J25: =SUMIFS(MISSIONS!$AB$3:$AB$2094,MISSIONS!$I$3:$I$2094,J$1)+J38 -> 228.4659 | ... N25: =SUMIFS(MISSIONS!$AB$3:$AB$2094,MISSIONS!$I$3:$I$2094,N$1)+N38 -> 18.4545
A26: =MISSIONS!AD2 -> Boom | B26: =SUM(C26:N26)+O26 -> 284.36262 | C26: =SUMIFS(MISSIONS!$AD$3:$AD$2094,MISSIONS!$I$3:$I$2094,C$1) -> 0 | D26: =SUMIFS(MISSIONS!$AD$3:$AD$2094,MISSIONS!$I$3:$I$2094,D$1) -> 0 | E26: =SUMIFS(MISSIONS!$AD$3:$AD$2094,MISSIONS!$I$3:$I$2094,E$1) -> 0 | F26: =SUMIFS(MISSIONS!$AD$3:$AD$2094,MISSIONS!$I$3:$I$2094,F$1) -> 0 | G26: =SUMIFS(MISSIONS!$AD$3:$AD$2094,MISSIONS!$I$3:$I$2094,G$1) -> 0 | H26: =SUMIFS(MISSIONS!$AD$3:$AD$2094,MISSIONS!$I$3:$I$2094,H$1) -> 0 | I26: =SUMIFS(MISSIONS!$AD$3:$AD$2094,MISSIONS!$I$3:$I$2094,I$1) -> 0 | J26: =SUMIFS(MISSIONS!$AD$3:$AD$2094,MISSIONS!$I$3:$I$2094,J$1) -> 0 | ... N26: =SUMIFS(MISSIONS!$AD$3:$AD$2094,MISSIONS!$I$3:$I$2094,N$1) -> 7.3818
A27: =MISSIONS!AF2 -> Damien | B27: =SUM(C27:N27)+O27 -> 0 | C27: =SUMIFS(MISSIONS!$AF$3:$AF$2094,MISSIONS!$I$3:$I$2094,C$1) -> 0 | D27: =SUMIFS(MISSIONS!$AF$3:$AF$2094,MISSIONS!$I$3:$I$2094,D$1) -> 0 | E27: =SUMIFS(MISSIONS!$AF$3:$AF$2094,MISSIONS!$I$3:$I$2094,E$1) -> 0 | F27: =SUMIFS(MISSIONS!$AF$3:$AF$2094,MISSIONS!$I$3:$I$2094,F$1) -> 0 | G27: =SUMIFS(MISSIONS!$AF$3:$AF$2094,MISSIONS!$I$3:$I$2094,G$1) -> 0 | H27: =SUMIFS(MISSIONS!$AF$3:$AF$2094,MISSIONS!$I$3:$I$2094,H$1) -> 0 | I27: =SUMIFS(MISSIONS!$AF$3:$AF$2094,MISSIONS!$I$3:$I$2094,I$1) -> 0 | J27: =SUMIFS(MISSIONS!$AF$3:$AF$2094,MISSIONS!$I$3:$I$2094,J$1) -> 0 | ... N27: =SUMIFS(MISSIONS!$AF$3:$AF$2094,MISSIONS!$I$3:$I$2094,N$1) -> 0
A28: =MISSIONS!AH2 -> Maitre | B28: =SUM(C28:N28)+O28 -> 0 | C28: =SUMIFS(MISSIONS!$AH$3:$AH$2094,MISSIONS!$I$3:$I$2094,C$1) -> 0 | D28: =SUMIFS(MISSIONS!$AH$3:$AH$2094,MISSIONS!$I$3:$I$2094,D$1) -> 0 | E28: =SUMIFS(MISSIONS!$AH$3:$AH$2094,MISSIONS!$I$3:$I$2094,E$1) -> 0 | F28: =SUMIFS(MISSIONS!$AH$3:$AH$2094,MISSIONS!$I$3:$I$2094,F$1) -> 0 | I28: =SUMIFS(MISSIONS!$AH$3:$AH$2094,MISSIONS!$I$3:$I$2094,I$1) -> 0 | L28: =SUMIFS(MISSIONS!$AH$3:$AH$2094,MISSIONS!$I$3:$I$2094,L$1) -> 0 | M28: =SUMIFS(MISSIONS!$AH$3:$AH$2094,MISSIONS!$I$3:$I$2094,M$1) -> 0 | N28: =SUMIFS(MISSIONS!$AH$3:$AH$2094,MISSIONS!$I$3:$I$2094,N$1) -> 0
A29: =MISSIONS!AJ2 -> x | B29: =SUM(C29:N29)+O29 -> 0 | C29: =SUMIFS(MISSIONS!$AJ$3:$AJ$2094,MISSIONS!$I$3:$I$2094,C$1) -> 0 | D29: =SUMIFS(MISSIONS!$AJ$3:$AJ$2094,MISSIONS!$I$3:$I$2094,D$1) -> 0 | E29: =SUMIFS(MISSIONS!$AJ$3:$AJ$2094,MISSIONS!$I$3:$I$2094,E$1) -> 0 | F29: =SUMIFS(MISSIONS!$AJ$3:$AJ$2094,MISSIONS!$I$3:$I$2094,F$1) -> 0 | G29: =SUMIFS(MISSIONS!$AJ$3:$AJ$2094,MISSIONS!$I$3:$I$2094,G$1) -> 0 | H29: =SUMIFS(MISSIONS!$AJ$3:$AJ$2094,MISSIONS!$I$3:$I$2094,H$1) -> 0 | I29: =SUMIFS(MISSIONS!$AJ$3:$AJ$2094,MISSIONS!$I$3:$I$2094,I$1) -> 0 | J29: =SUMIFS(MISSIONS!$AJ$3:$AJ$2094,MISSIONS!$I$3:$I$2094,J$1) -> 0 | ... N29: =SUMIFS(MISSIONS!$AJ$3:$AJ$2094,MISSIONS!$I$3:$I$2094,N$1) -> 0
A30: =MISSIONS!AL2 -> x | B30: =SUM(C30:N30)+O30 -> 0 | C30: =SUMIFS(MISSIONS!$AL$3:$AL$2094,MISSIONS!$I$3:$I$2094,C$1)+C40 -> 0 | D30: =SUMIFS(MISSIONS!$AL$3:$AL$2094,MISSIONS!$I$3:$I$2094,D$1)+D40 -> 0 | E30: =SUMIFS(MISSIONS!$AL$3:$AL$2094,MISSIONS!$I$3:$I$2094,E$1)+E40 -> 0 | F30: =SUMIFS(MISSIONS!$AL$3:$AL$2094,MISSIONS!$I$3:$I$2094,F$1)+F40 -> 0 | G30: =SUMIFS(MISSIONS!$AL$3:$AL$2094,MISSIONS!$I$3:$I$2094,G$1)+G40 -> 0 | H30: =SUMIFS(MISSIONS!$AL$3:$AL$2094,MISSIONS!$I$3:$I$2094,H$1)+H40 -> 0 | I30: =SUMIFS(MISSIONS!$AL$3:$AL$2094,MISSIONS!$I$3:$I$2094,I$1)+I40 -> 0 | J30: =SUMIFS(MISSIONS!$AL$3:$AL$2094,MISSIONS!$I$3:$I$2094,J$1)+J40 -> 0 | ... N30: =SUMIFS(MISSIONS!$AL$3:$AL$2094,MISSIONS!$I$3:$I$2094,N$1)+N40 -> 0
A31: =MISSIONS!AN2 -> x | B31: =SUM(C31:N31)+O31 -> 0 | C31: =SUMIFS(MISSIONS!$AP$3:$AP$2094,MISSIONS!$I$3:$I$2094,C$1) -> 0 | D31: =SUMIFS(MISSIONS!$AN$3:$AN$2094,MISSIONS!$I$3:$I$2094,D$1) -> 0 | E31: =SUMIFS(MISSIONS!$AN$3:$AN$2094,MISSIONS!$I$3:$I$2094,E$1) -> 0 | F31: =SUMIFS(MISSIONS!$AN$3:$AN$2094,MISSIONS!$I$3:$I$2094,F$1) -> 0 | G31: =SUMIFS(MISSIONS!$AN$3:$AN$2094,MISSIONS!$I$3:$I$2094,G$1) -> 0 | H31: =SUMIFS(MISSIONS!$AN$3:$AN$2094,MISSIONS!$I$3:$I$2094,H$1) -> 0 | I31: =SUMIFS(MISSIONS!$AN$3:$AN$2094,MISSIONS!$I$3:$I$2094,I$1) -> 0 | J31: =SUMIFS(MISSIONS!$AN$3:$AN$2094,MISSIONS!$I$3:$I$2094,J$1) -> 0 | K31: =SUMIFS(MISSIONS!$AN$3:$AN$2094,MISSIONS!$I$3:$I$2094,K$1) -> 0 | ... N31: =SUMIFS(MISSIONS!$AN$3:$AN$2094,MISSIONS!$I$3:$I$2094,N$1) -> 0
A32: =MISSIONS!AP2 -> x | B32: =SUM(C32:N32)+O32 -> 0 | C32: =SUMIFS(MISSIONS!$AP$3:$AP$2094,MISSIONS!$I$3:$I$2094,C$1) -> 0 | D32: =SUMIFS(MISSIONS!$AP$3:$AP$2094,MISSIONS!$I$3:$I$2094,D$1) -> 0 | E32: =SUMIFS(MISSIONS!$AP$3:$AP$2094,MISSIONS!$I$3:$I$2094,E$1) -> 0 | F32: =SUMIFS(MISSIONS!$AP$3:$AP$2094,MISSIONS!$I$3:$I$2094,F$1) -> 0 | G32: =SUMIFS(MISSIONS!$AP$3:$AP$2094,MISSIONS!$I$3:$I$2094,G$1) -> 0 | H32: =SUMIFS(MISSIONS!$AP$3:$AP$2094,MISSIONS!$I$3:$I$2094,H$1) -> 0 | I32: =SUMIFS(MISSIONS!$AP$3:$AP$2094,MISSIONS!$I$3:$I$2094,I$1) -> 0 | J32: =SUMIFS(MISSIONS!$AP$3:$AP$2094,MISSIONS!$I$3:$I$2094,J$1) -> 0 | ... N32: =SUMIFS(MISSIONS!$AP$3:$AP$2094,MISSIONS!$I$3:$I$2094,N$1) -> 0
A33: =MISSIONS!AR2 -> x | B33: =SUM(C33:N33)+O33 -> 0 | C33: =SUMIFS(MISSIONS!$AR$3:$AR$2094,MISSIONS!$I$3:$I$2094,C$1) -> 0 | D33: =SUMIFS(MISSIONS!$AR$3:$AR$2094,MISSIONS!$I$3:$I$2094,D$1) -> 0 | E33: =SUMIFS(MISSIONS!$AR$3:$AR$2094,MISSIONS!$I$3:$I$2094,E$1) -> 0 | F33: =SUMIFS(MISSIONS!$AR$3:$AR$2094,MISSIONS!$I$3:$I$2094,F$1) -> 0 | G33: =SUMIFS(MISSIONS!$AR$3:$AR$2094,MISSIONS!$I$3:$I$2094,G$1) -> 0 | H33: =SUMIFS(MISSIONS!$AR$3:$AR$2094,MISSIONS!$I$3:$I$2094,H$1) -> 0 | I33: =SUMIFS(MISSIONS!$AR$3:$AR$2094,MISSIONS!$I$3:$I$2094,I$1) -> 0 | J33: =SUMIFS(MISSIONS!$AR$3:$AR$2094,MISSIONS!$I$3:$I$2094,J$1) -> 0 | ... M33: =SUMIFS(MISSIONS!$AR$3:$AR$2094,MISSIONS!$I$3:$I$2094,M$1) -> 0
A35: Reste | B35: =SUM(C35:N35) -> 17919.745 | C35: =C5-SUM(C10:C17)-SUM(C22:C33) -> 697.93408 | D35: =D5-SUM(D10:D17)-SUM(D22:D33) -> 697.04408 | E35: =E5-SUM(E10:E17)-SUM(E22:E33) -> 1077.8202 | F35: =F5-SUM(F10:F17)-SUM(F22:F33) -> 654.53412 | G35: =G5-SUM(G10:G17)-SUM(G22:G33) -> 1682.7095 | H35: =H5-SUM(H10:H17)-SUM(H22:H33) -> 3221.2377 | I35: =I5-SUM(I10:I17)-SUM(I22:I33) -> 636.45957 | J35: =J5-SUM(J10:J17)-SUM(J22:J33) -> 595.24074 | ... N35: =N5-SUM(N10:N17)-SUM(N22:N33) -> -149.4697
A37: APPORTEURS
A38: =Données!$A2 -> Eric A | B38: =SUM(C38:N38) -> 0 | C38: =SUMIFS(MISSIONS!$B$3:$B$2094,MISSIONS!$I$3:$I$2094,C$1,MISSIONS!$A$3:$A$2094,Données!$A2)+ SUMIFS(MISSIONS!$D$3:$D$2094,MISSIONS!$I$3:$I$2094,C$1,MISSIONS!$C$3:$C$2094,Données!$A2) -> 0 | D38: =SUMIFS(MISSIONS!$B$3:$B$2094,MISSIONS!$I$3:$I$2094,D$1,MISSIONS!$A$3:$A$2094,Données!$A2)+ SUMIFS(MISSIONS!$D$3:$D$2094,MISSIONS!$I$3:$I$2094,D$1,MISSIONS!$C$3:$C$2094,Données!$A2) -> 0 | E38: =SUMIFS(MISSIONS!$B$3:$B$2094,MISSIONS!$I$3:$I$2094,E$1,MISSIONS!$A$3:$A$2094,Données!$A2)+ SUMIFS(MISSIONS!$D$3:$D$2094,MISSIONS!$I$3:$I$2094,E$1,MISSIONS!$C$3:$C$2094,Données!$A2) -> 0 | F38: =SUMIFS(MISSIONS!$B$3:$B$2094,MISSIONS!$I$3:$I$2094,F$1,MISSIONS!$A$3:$A$2094,Données!$A2)+ SUMIFS(MISSIONS!$D$3:$D$2094,MISSIONS!$I$3:$I$2094,F$1,MISSIONS!$C$3:$C$2094,Données!$A2) -> 0 | G38: =SUMIFS(MISSIONS!$B$3:$B$2094,MISSIONS!$I$3:$I$2094,G$1,MISSIONS!$A$3:$A$2094,Données!$A2)+ SUMIFS(MISSIONS!$D$3:$D$2094,MISSIONS!$I$3:$I$2094,G$1,MISSIONS!$C$3:$C$2094,Données!$A2) -> 0 | H38: =SUMIFS(MISSIONS!$B$3:$B$2094,MISSIONS!$I$3:$I$2094,H$1,MISSIONS!$A$3:$A$2094,Données!$A2)+ SUMIFS(MISSIONS!$D$3:$D$2094,MISSIONS!$I$3:$I$2094,H$1,MISSIONS!$C$3:$C$2094,Données!$A2) -> 0 | I38: =SUMIFS(MISSIONS!$B$3:$B$2094,MISSIONS!$I$3:$I$2094,I$1,MISSIONS!$A$3:$A$2094,Données!$A2)+ SUMIFS(MISSIONS!$D$3:$D$2094,MISSIONS!$I$3:$I$2094,I$1,MISSIONS!$C$3:$C$2094,Données!$A2) -> 0 | J38: =SUMIFS(MISSIONS!$B$3:$B$2094,MISSIONS!$I$3:$I$2094,J$1,MISSIONS!$A$3:$A$2094,Données!$A2)+ SUMIFS(MISSIONS!$D$3:$D$2094,MISSIONS!$I$3:$I$2094,J$1,MISSIONS!$C$3:$C$2094,Données!$A2) -> 0 | ... N38: =SUMIFS(MISSIONS!$B$3:$B$2094,MISSIONS!$I$3:$I$2094,N$1,MISSIONS!$A$3:$A$2094,Données!$A2)+ SUMIFS(MISSIONS!$D$3:$D$2094,MISSIONS!$I$3:$I$2094,N$1,MISSIONS!$C$3:$C$2094,Données!$A2) -> 0
A39: =Données!$A3 -> Fred | B39: =SUM(C39:N39) -> 0 | C39: =SUMIFS(MISSIONS!$B$3:$B$2094,MISSIONS!$I$3:$I$2094,C$1,MISSIONS!$A$3:$A$2094,Données!$A3)+ SUMIFS(MISSIONS!$D$3:$D$2094,MISSIONS!$I$3:$I$2094,C$1,MISSIONS!$C$3:$C$2094,Données!$A3) -> 0 | D39: =SUMIFS(MISSIONS!$B$3:$B$2094,MISSIONS!$I$3:$I$2094,D$1,MISSIONS!$A$3:$A$2094,Données!$A3)+ SUMIFS(MISSIONS!$D$3:$D$2094,MISSIONS!$I$3:$I$2094,D$1,MISSIONS!$C$3:$C$2094,Données!$A3) -> 0 | E39: =SUMIFS(MISSIONS!$B$3:$B$2094,MISSIONS!$I$3:$I$2094,E$1,MISSIONS!$A$3:$A$2094,Données!$A3)+ SUMIFS(MISSIONS!$D$3:$D$2094,MISSIONS!$I$3:$I$2094,E$1,MISSIONS!$C$3:$C$2094,Données!$A3) -> 0 | F39: =SUMIFS(MISSIONS!$B$3:$B$2094,MISSIONS!$I$3:$I$2094,F$1,MISSIONS!$A$3:$A$2094,Données!$A3)+ SUMIFS(MISSIONS!$D$3:$D$2094,MISSIONS!$I$3:$I$2094,F$1,MISSIONS!$C$3:$C$2094,Données!$A3) -> 0 | G39: =SUMIFS(MISSIONS!$B$3:$B$2094,MISSIONS!$I$3:$I$2094,G$1,MISSIONS!$A$3:$A$2094,Données!$A3)+ SUMIFS(MISSIONS!$D$3:$D$2094,MISSIONS!$I$3:$I$2094,G$1,MISSIONS!$C$3:$C$2094,Données!$A3) -> 0 | H39: =SUMIFS(MISSIONS!$B$3:$B$2094,MISSIONS!$I$3:$I$2094,H$1,MISSIONS!$A$3:$A$2094,Données!$A3)+ SUMIFS(MISSIONS!$D$3:$D$2094,MISSIONS!$I$3:$I$2094,H$1,MISSIONS!$C$3:$C$2094,Données!$A3) -> 0 | I39: =SUMIFS(MISSIONS!$B$3:$B$2094,MISSIONS!$I$3:$I$2094,I$1,MISSIONS!$A$3:$A$2094,Données!$A3)+ SUMIFS(MISSIONS!$D$3:$D$2094,MISSIONS!$I$3:$I$2094,I$1,MISSIONS!$C$3:$C$2094,Données!$A3) -> 0 | J39: =SUMIFS(MISSIONS!$B$3:$B$2094,MISSIONS!$I$3:$I$2094,J$1,MISSIONS!$A$3:$A$2094,Données!$A3)+ SUMIFS(MISSIONS!$D$3:$D$2094,MISSIONS!$I$3:$I$2094,J$1,MISSIONS!$C$3:$C$2094,Données!$A3) -> 0 | ... N39: =SUMIFS(MISSIONS!$B$3:$B$2094,MISSIONS!$I$3:$I$2094,N$1,MISSIONS!$A$3:$A$2094,Données!$A3)+ SUMIFS(MISSIONS!$D$3:$D$2094,MISSIONS!$I$3:$I$2094,N$1,MISSIONS!$C$3:$C$2094,Données!$A3) -> 0
A40: =Données!$A4 -> Hervé | B40: =SUM(C40:N40) -> 0 | C40: =SUMIFS(MISSIONS!$B$3:$B$2094,MISSIONS!$I$3:$I$2094,C$1,MISSIONS!$A$3:$A$2094,Données!$A4)+ SUMIFS(MISSIONS!$D$3:$D$2094,MISSIONS!$I$3:$I$2094,C$1,MISSIONS!$C$3:$C$2094,Données!$A4) -> 0 | D40: =SUMIFS(MISSIONS!$B$3:$B$2094,MISSIONS!$I$3:$I$2094,D$1,MISSIONS!$A$3:$A$2094,Données!$A4)+ SUMIFS(MISSIONS!$D$3:$D$2094,MISSIONS!$I$3:$I$2094,D$1,MISSIONS!$C$3:$C$2094,Données!$A4) -> 0 | E40: =SUMIFS(MISSIONS!$B$3:$B$2094,MISSIONS!$I$3:$I$2094,E$1,MISSIONS!$A$3:$A$2094,Données!$A4)+ SUMIFS(MISSIONS!$D$3:$D$2094,MISSIONS!$I$3:$I$2094,E$1,MISSIONS!$C$3:$C$2094,Données!$A4) -> 0 | F40: =SUMIFS(MISSIONS!$B$3:$B$2094,MISSIONS!$I$3:$I$2094,F$1,MISSIONS!$A$3:$A$2094,Données!$A4)+ SUMIFS(MISSIONS!$D$3:$D$2094,MISSIONS!$I$3:$I$2094,F$1,MISSIONS!$C$3:$C$2094,Données!$A4) -> 0 | G40: =SUMIFS(MISSIONS!$B$3:$B$2094,MISSIONS!$I$3:$I$2094,G$1,MISSIONS!$A$3:$A$2094,Données!$A4)+ SUMIFS(MISSIONS!$D$3:$D$2094,MISSIONS!$I$3:$I$2094,G$1,MISSIONS!$C$3:$C$2094,Données!$A4) -> 0 | H40: =SUMIFS(MISSIONS!$B$3:$B$2094,MISSIONS!$I$3:$I$2094,H$1,MISSIONS!$A$3:$A$2094,Données!$A4)+ SUMIFS(MISSIONS!$D$3:$D$2094,MISSIONS!$I$3:$I$2094,H$1,MISSIONS!$C$3:$C$2094,Données!$A4) -> 0 | I40: =SUMIFS(MISSIONS!$B$3:$B$2094,MISSIONS!$I$3:$I$2094,I$1,MISSIONS!$A$3:$A$2094,Données!$A4)+ SUMIFS(MISSIONS!$D$3:$D$2094,MISSIONS!$I$3:$I$2094,I$1,MISSIONS!$C$3:$C$2094,Données!$A4) -> 0 | J40: =SUMIFS(MISSIONS!$B$3:$B$2094,MISSIONS!$I$3:$I$2094,J$1,MISSIONS!$A$3:$A$2094,Données!$A4)+ SUMIFS(MISSIONS!$D$3:$D$2094,MISSIONS!$I$3:$I$2094,J$1,MISSIONS!$C$3:$C$2094,Données!$A4) -> 0 | ... N40: =SUMIFS(MISSIONS!$B$3:$B$2094,MISSIONS!$I$3:$I$2094,N$1,MISSIONS!$A$3:$A$2094,Données!$A4)+ SUMIFS(MISSIONS!$D$3:$D$2094,MISSIONS!$I$3:$I$2094,N$1,MISSIONS!$C$3:$C$2094,Données!$A4) -> 0
A41: =Données!$A5 -> Dono | B41: =SUM(C41:N41) -> 0 | C41: =SUMIFS(MISSIONS!$B$3:$B$2094,MISSIONS!$I$3:$I$2094,C$1,MISSIONS!$A$3:$A$2094,Données!$A5)+ SUMIFS(MISSIONS!$D$3:$D$2094,MISSIONS!$I$3:$I$2094,C$1,MISSIONS!$C$3:$C$2094,Données!$A5) -> 0 | D41: =SUMIFS(MISSIONS!$B$3:$B$2094,MISSIONS!$I$3:$I$2094,D$1,MISSIONS!$A$3:$A$2094,Données!$A5)+ SUMIFS(MISSIONS!$D$3:$D$2094,MISSIONS!$I$3:$I$2094,D$1,MISSIONS!$C$3:$C$2094,Données!$A5) -> 0 | E41: =SUMIFS(MISSIONS!$B$3:$B$2094,MISSIONS!$I$3:$I$2094,E$1,MISSIONS!$A$3:$A$2094,Données!$A5)+ SUMIFS(MISSIONS!$D$3:$D$2094,MISSIONS!$I$3:$I$2094,E$1,MISSIONS!$C$3:$C$2094,Données!$A5) -> 0 | F41: =SUMIFS(MISSIONS!$B$3:$B$2094,MISSIONS!$I$3:$I$2094,F$1,MISSIONS!$A$3:$A$2094,Données!$A5)+ SUMIFS(MISSIONS!$D$3:$D$2094,MISSIONS!$I$3:$I$2094,F$1,MISSIONS!$C$3:$C$2094,Données!$A5) -> 0 | G41: =SUMIFS(MISSIONS!$B$3:$B$2094,MISSIONS!$I$3:$I$2094,G$1,MISSIONS!$A$3:$A$2094,Données!$A5)+ SUMIFS(MISSIONS!$D$3:$D$2094,MISSIONS!$I$3:$I$2094,G$1,MISSIONS!$C$3:$C$2094,Données!$A5) -> 0 | H41: =SUMIFS(MISSIONS!$B$3:$B$2094,MISSIONS!$I$3:$I$2094,H$1,MISSIONS!$A$3:$A$2094,Données!$A5)+ SUMIFS(MISSIONS!$D$3:$D$2094,MISSIONS!$I$3:$I$2094,H$1,MISSIONS!$C$3:$C$2094,Données!$A5) -> 0 | I41: =SUMIFS(MISSIONS!$B$3:$B$2094,MISSIONS!$I$3:$I$2094,I$1,MISSIONS!$A$3:$A$2094,Données!$A5)+ SUMIFS(MISSIONS!$D$3:$D$2094,MISSIONS!$I$3:$I$2094,I$1,MISSIONS!$C$3:$C$2094,Données!$A5) -> 0 | J41: =SUMIFS(MISSIONS!$B$3:$B$2094,MISSIONS!$I$3:$I$2094,J$1,MISSIONS!$A$3:$A$2094,Données!$A5)+ SUMIFS(MISSIONS!$D$3:$D$2094,MISSIONS!$I$3:$I$2094,J$1,MISSIONS!$C$3:$C$2094,Données!$A5) -> 0 | ... N41: =SUMIFS(MISSIONS!$B$3:$B$2094,MISSIONS!$I$3:$I$2094,N$1,MISSIONS!$A$3:$A$2094,Données!$A5)+ SUMIFS(MISSIONS!$D$3:$D$2094,MISSIONS!$I$3:$I$2094,N$1,MISSIONS!$C$3:$C$2094,Données!$A5) -> 0
A42: =Données!$A6 -> Colpa | B42: =SUM(C42:N42) -> 656.27 | C42: =SUMIFS(MISSIONS!$B$3:$B$2094,MISSIONS!$I$3:$I$2094,C$1,MISSIONS!$A$3:$A$2094,Données!$A6)+ SUMIFS(MISSIONS!$D$3:$D$2094,MISSIONS!$I$3:$I$2094,C$1,MISSIONS!$C$3:$C$2094,Données!$A6) -> 0 | D42: =SUMIFS(MISSIONS!$B$3:$B$2094,MISSIONS!$I$3:$I$2094,D$1,MISSIONS!$A$3:$A$2094,Données!$A6)+ SUMIFS(MISSIONS!$D$3:$D$2094,MISSIONS!$I$3:$I$2094,D$1,MISSIONS!$C$3:$C$2094,Données!$A6) -> 0 | E42: =SUMIFS(MISSIONS!$B$3:$B$2094,MISSIONS!$I$3:$I$2094,E$1,MISSIONS!$A$3:$A$2094,Données!$A6)+ SUMIFS(MISSIONS!$D$3:$D$2094,MISSIONS!$I$3:$I$2094,E$1,MISSIONS!$C$3:$C$2094,Données!$A6) -> 44.64 | F42: =SUMIFS(MISSIONS!$B$3:$B$2094,MISSIONS!$I$3:$I$2094,F$1,MISSIONS!$A$3:$A$2094,Données!$A6)+ SUMIFS(MISSIONS!$D$3:$D$2094,MISSIONS!$I$3:$I$2094,F$1,MISSIONS!$C$3:$C$2094,Données!$A6) -> 44.64 | G42: =SUMIFS(MISSIONS!$B$3:$B$2094,MISSIONS!$I$3:$I$2094,G$1,MISSIONS!$A$3:$A$2094,Données!$A6)+ SUMIFS(MISSIONS!$D$3:$D$2094,MISSIONS!$I$3:$I$2094,G$1,MISSIONS!$C$3:$C$2094,Données!$A6) -> 44.64 | H42: =SUMIFS(MISSIONS!$B$3:$B$2094,MISSIONS!$I$3:$I$2094,H$1,MISSIONS!$A$3:$A$2094,Données!$A6)+ SUMIFS(MISSIONS!$D$3:$D$2094,MISSIONS!$I$3:$I$2094,H$1,MISSIONS!$C$3:$C$2094,Données!$A6) -> 50.22 | I42: =SUMIFS(MISSIONS!$B$3:$B$2094,MISSIONS!$I$3:$I$2094,I$1,MISSIONS!$A$3:$A$2094,Données!$A6)+ SUMIFS(MISSIONS!$D$3:$D$2094,MISSIONS!$I$3:$I$2094,I$1,MISSIONS!$C$3:$C$2094,Données!$A6) -> 64.8675 | J42: =SUMIFS(MISSIONS!$B$3:$B$2094,MISSIONS!$I$3:$I$2094,J$1,MISSIONS!$A$3:$A$2094,Données!$A6)+ SUMIFS(MISSIONS!$D$3:$D$2094,MISSIONS!$I$3:$I$2094,J$1,MISSIONS!$C$3:$C$2094,Données!$A6) -> 129.735 | ... N42: =SUMIFS(MISSIONS!$B$3:$B$2094,MISSIONS!$I$3:$I$2094,N$1,MISSIONS!$A$3:$A$2094,Données!$A6)+ SUMIFS(MISSIONS!$D$3:$D$2094,MISSIONS!$I$3:$I$2094,N$1,MISSIONS!$C$3:$C$2094,Données!$A6) -> 0
A43: =Données!$A7 -> Na Oya | B43: =SUM(C43:N43) -> 638.6496 | C43: =SUMIFS(MISSIONS!$B$3:$B$2094,MISSIONS!$I$3:$I$2094,C$1,MISSIONS!$A$3:$A$2094,Données!$A7)+ SUMIFS(MISSIONS!$D$3:$D$2094,MISSIONS!$I$3:$I$2094,C$1,MISSIONS!$C$3:$C$2094,Données!$A7) -> 113.9808 | D43: =SUMIFS(MISSIONS!$B$3:$B$2094,MISSIONS!$I$3:$I$2094,D$1,MISSIONS!$A$3:$A$2094,Données!$A7)+ SUMIFS(MISSIONS!$D$3:$D$2094,MISSIONS!$I$3:$I$2094,D$1,MISSIONS!$C$3:$C$2094,Données!$A7) -> 113.9808 | E43: =SUMIFS(MISSIONS!$B$3:$B$2094,MISSIONS!$I$3:$I$2094,E$1,MISSIONS!$A$3:$A$2094,Données!$A7)+ SUMIFS(MISSIONS!$D$3:$D$2094,MISSIONS!$I$3:$I$2094,E$1,MISSIONS!$C$3:$C$2094,Données!$A7) -> 114.09984 | F43: =SUMIFS(MISSIONS!$B$3:$B$2094,MISSIONS!$I$3:$I$2094,F$1,MISSIONS!$A$3:$A$2094,Données!$A7)+ SUMIFS(MISSIONS!$D$3:$D$2094,MISSIONS!$I$3:$I$2094,F$1,MISSIONS!$C$3:$C$2094,Données!$A7) -> 114.09984 | G43: =SUMIFS(MISSIONS!$B$3:$B$2094,MISSIONS!$I$3:$I$2094,G$1,MISSIONS!$A$3:$A$2094,Données!$A7)+ SUMIFS(MISSIONS!$D$3:$D$2094,MISSIONS!$I$3:$I$2094,G$1,MISSIONS!$C$3:$C$2094,Données!$A7) -> 114.21888 | H43: =SUMIFS(MISSIONS!$B$3:$B$2094,MISSIONS!$I$3:$I$2094,H$1,MISSIONS!$A$3:$A$2094,Données!$A7)+ SUMIFS(MISSIONS!$D$3:$D$2094,MISSIONS!$I$3:$I$2094,H$1,MISSIONS!$C$3:$C$2094,Données!$A7) -> 68.26944 | I43: =SUMIFS(MISSIONS!$B$3:$B$2094,MISSIONS!$I$3:$I$2094,I$1,MISSIONS!$A$3:$A$2094,Données!$A7)+ SUMIFS(MISSIONS!$D$3:$D$2094,MISSIONS!$I$3:$I$2094,I$1,MISSIONS!$C$3:$C$2094,Données!$A7) -> 0 | J43: =SUMIFS(MISSIONS!$B$3:$B$2094,MISSIONS!$I$3:$I$2094,J$1,MISSIONS!$A$3:$A$2094,Données!$A7)+ SUMIFS(MISSIONS!$D$3:$D$2094,MISSIONS!$I$3:$I$2094,J$1,MISSIONS!$C$3:$C$2094,Données!$A7) -> 0 | ... N43: =SUMIFS(MISSIONS!$B$3:$B$2094,MISSIONS!$I$3:$I$2094,N$1,MISSIONS!$A$3:$A$2094,Données!$A7)+ SUMIFS(MISSIONS!$D$3:$D$2094,MISSIONS!$I$3:$I$2094,N$1,MISSIONS!$C$3:$C$2094,Données!$A7) -> 0
A44: =Données!$A8 -> B&A | B44: =SUM(C44:N44) -> 0 | C44: =SUMIFS(MISSIONS!$B$3:$B$2094,MISSIONS!$I$3:$I$2094,C$1,MISSIONS!$A$3:$A$2094,Données!$A8)+ SUMIFS(MISSIONS!$D$3:$D$2094,MISSIONS!$I$3:$I$2094,C$1,MISSIONS!$C$3:$C$2094,Données!$A8) -> 0 | D44: =SUMIFS(MISSIONS!$B$3:$B$2094,MISSIONS!$I$3:$I$2094,D$1,MISSIONS!$A$3:$A$2094,Données!$A8)+ SUMIFS(MISSIONS!$D$3:$D$2094,MISSIONS!$I$3:$I$2094,D$1,MISSIONS!$C$3:$C$2094,Données!$A8) -> 0 | E44: =SUMIFS(MISSIONS!$B$3:$B$2094,MISSIONS!$I$3:$I$2094,E$1,MISSIONS!$A$3:$A$2094,Données!$A8)+ SUMIFS(MISSIONS!$D$3:$D$2094,MISSIONS!$I$3:$I$2094,E$1,MISSIONS!$C$3:$C$2094,Données!$A8) -> 0 | F44: =SUMIFS(MISSIONS!$B$3:$B$2094,MISSIONS!$I$3:$I$2094,F$1,MISSIONS!$A$3:$A$2094,Données!$A8)+ SUMIFS(MISSIONS!$D$3:$D$2094,MISSIONS!$I$3:$I$2094,F$1,MISSIONS!$C$3:$C$2094,Données!$A8) -> 0 | G44: =SUMIFS(MISSIONS!$B$3:$B$2094,MISSIONS!$I$3:$I$2094,G$1,MISSIONS!$A$3:$A$2094,Données!$A8)+ SUMIFS(MISSIONS!$D$3:$D$2094,MISSIONS!$I$3:$I$2094,G$1,MISSIONS!$C$3:$C$2094,Données!$A8) -> 0 | H44: =SUMIFS(MISSIONS!$B$3:$B$2094,MISSIONS!$I$3:$I$2094,H$1,MISSIONS!$A$3:$A$2094,Données!$A8)+ SUMIFS(MISSIONS!$D$3:$D$2094,MISSIONS!$I$3:$I$2094,H$1,MISSIONS!$C$3:$C$2094,Données!$A8) -> 0 | I44: =SUMIFS(MISSIONS!$B$3:$B$2094,MISSIONS!$I$3:$I$2094,I$1,MISSIONS!$A$3:$A$2094,Données!$A8)+ SUMIFS(MISSIONS!$D$3:$D$2094,MISSIONS!$I$3:$I$2094,I$1,MISSIONS!$C$3:$C$2094,Données!$A8) -> 0 | J44: =SUMIFS(MISSIONS!$B$3:$B$2094,MISSIONS!$I$3:$I$2094,J$1,MISSIONS!$A$3:$A$2094,Données!$A8)+ SUMIFS(MISSIONS!$D$3:$D$2094,MISSIONS!$I$3:$I$2094,J$1,MISSIONS!$C$3:$C$2094,Données!$A8) -> 0 | ... N44: =SUMIFS(MISSIONS!$B$3:$B$2094,MISSIONS!$I$3:$I$2094,N$1,MISSIONS!$A$3:$A$2094,Données!$A8)+ SUMIFS(MISSIONS!$D$3:$D$2094,MISSIONS!$I$3:$I$2094,N$1,MISSIONS!$C$3:$C$2094,Données!$A8) -> 0
A45: =Données!$A9 -> Vero | B45: =SUM(C45:N45) -> 213.0342 | C45: =SUMIFS(MISSIONS!$B$3:$B$2094,MISSIONS!$I$3:$I$2094,C$1,MISSIONS!$A$3:$A$2094,Données!$A9)+ SUMIFS(MISSIONS!$D$3:$D$2094,MISSIONS!$I$3:$I$2094,C$1,MISSIONS!$C$3:$C$2094,Données!$A9) -> 10.59456 | D45: =SUMIFS(MISSIONS!$B$3:$B$2094,MISSIONS!$I$3:$I$2094,D$1,MISSIONS!$A$3:$A$2094,Données!$A9)+ SUMIFS(MISSIONS!$D$3:$D$2094,MISSIONS!$I$3:$I$2094,D$1,MISSIONS!$C$3:$C$2094,Données!$A9) -> 10.59456 | E45: =SUMIFS(MISSIONS!$B$3:$B$2094,MISSIONS!$I$3:$I$2094,E$1,MISSIONS!$A$3:$A$2094,Données!$A9)+ SUMIFS(MISSIONS!$D$3:$D$2094,MISSIONS!$I$3:$I$2094,E$1,MISSIONS!$C$3:$C$2094,Données!$A9) -> 10.59456 | F45: =SUMIFS(MISSIONS!$B$3:$B$2094,MISSIONS!$I$3:$I$2094,F$1,MISSIONS!$A$3:$A$2094,Données!$A9)+ SUMIFS(MISSIONS!$D$3:$D$2094,MISSIONS!$I$3:$I$2094,F$1,MISSIONS!$C$3:$C$2094,Données!$A9) -> 10.59456 | G45: =SUMIFS(MISSIONS!$B$3:$B$2094,MISSIONS!$I$3:$I$2094,G$1,MISSIONS!$A$3:$A$2094,Données!$A9)+ SUMIFS(MISSIONS!$D$3:$D$2094,MISSIONS!$I$3:$I$2094,G$1,MISSIONS!$C$3:$C$2094,Données!$A9) -> 10.59456 | H45: =SUMIFS(MISSIONS!$B$3:$B$2094,MISSIONS!$I$3:$I$2094,H$1,MISSIONS!$A$3:$A$2094,Données!$A9)+ SUMIFS(MISSIONS!$D$3:$D$2094,MISSIONS!$I$3:$I$2094,H$1,MISSIONS!$C$3:$C$2094,Données!$A9) -> 10.7136 | I45: =SUMIFS(MISSIONS!$B$3:$B$2094,MISSIONS!$I$3:$I$2094,I$1,MISSIONS!$A$3:$A$2094,Données!$A9)+ SUMIFS(MISSIONS!$D$3:$D$2094,MISSIONS!$I$3:$I$2094,I$1,MISSIONS!$C$3:$C$2094,Données!$A9) -> 12.0528 | J45: =SUMIFS(MISSIONS!$B$3:$B$2094,MISSIONS!$I$3:$I$2094,J$1,MISSIONS!$A$3:$A$2094,Données!$A9)+ SUMIFS(MISSIONS!$D$3:$D$2094,MISSIONS!$I$3:$I$2094,J$1,MISSIONS!$C$3:$C$2094,Données!$A9) -> 15.066 | ... N45: =SUMIFS(MISSIONS!$B$3:$B$2094,MISSIONS!$I$3:$I$2094,N$1,MISSIONS!$A$3:$A$2094,Données!$A9)+ SUMIFS(MISSIONS!$D$3:$D$2094,MISSIONS!$I$3:$I$2094,N$1,MISSIONS!$C$3:$C$2094,Données!$A9) -> 36
A46: =Données!$A10 -> Sns | B46: =SUM(C46:N46) -> 0 | C46: =SUMIFS(MISSIONS!$B$3:$B$2094,MISSIONS!$I$3:$I$2094,C$1,MISSIONS!$A$3:$A$2094,Données!$A10)+ SUMIFS(MISSIONS!$D$3:$D$2094,MISSIONS!$I$3:$I$2094,C$1,MISSIONS!$C$3:$C$2094,Données!$A10) -> 0 | D46: =SUMIFS(MISSIONS!$B$3:$B$2094,MISSIONS!$I$3:$I$2094,D$1,MISSIONS!$A$3:$A$2094,Données!$A10)+ SUMIFS(MISSIONS!$D$3:$D$2094,MISSIONS!$I$3:$I$2094,D$1,MISSIONS!$C$3:$C$2094,Données!$A10) -> 0 | E46: =SUMIFS(MISSIONS!$B$3:$B$2094,MISSIONS!$I$3:$I$2094,E$1,MISSIONS!$A$3:$A$2094,Données!$A10)+ SUMIFS(MISSIONS!$D$3:$D$2094,MISSIONS!$I$3:$I$2094,E$1,MISSIONS!$C$3:$C$2094,Données!$A10) -> 0 | F46: =SUMIFS(MISSIONS!$B$3:$B$2094,MISSIONS!$I$3:$I$2094,F$1,MISSIONS!$A$3:$A$2094,Données!$A10)+ SUMIFS(MISSIONS!$D$3:$D$2094,MISSIONS!$I$3:$I$2094,F$1,MISSIONS!$C$3:$C$2094,Données!$A10) -> 0 | G46: =SUMIFS(MISSIONS!$B$3:$B$2094,MISSIONS!$I$3:$I$2094,G$1,MISSIONS!$A$3:$A$2094,Données!$A10)+ SUMIFS(MISSIONS!$D$3:$D$2094,MISSIONS!$I$3:$I$2094,G$1,MISSIONS!$C$3:$C$2094,Données!$A10) -> 0 | H46: =SUMIFS(MISSIONS!$B$3:$B$2094,MISSIONS!$I$3:$I$2094,H$1,MISSIONS!$A$3:$A$2094,Données!$A10)+ SUMIFS(MISSIONS!$D$3:$D$2094,MISSIONS!$I$3:$I$2094,H$1,MISSIONS!$C$3:$C$2094,Données!$A10) -> 0 | I46: =SUMIFS(MISSIONS!$B$3:$B$2094,MISSIONS!$I$3:$I$2094,I$1,MISSIONS!$A$3:$A$2094,Données!$A10)+ SUMIFS(MISSIONS!$D$3:$D$2094,MISSIONS!$I$3:$I$2094,I$1,MISSIONS!$C$3:$C$2094,Données!$A10) -> 0 | J46: =SUMIFS(MISSIONS!$B$3:$B$2094,MISSIONS!$I$3:$I$2094,J$1,MISSIONS!$A$3:$A$2094,Données!$A10)+ SUMIFS(MISSIONS!$D$3:$D$2094,MISSIONS!$I$3:$I$2094,J$1,MISSIONS!$C$3:$C$2094,Données!$A10) -> 0 | ... N46: =SUMIFS(MISSIONS!$B$3:$B$2094,MISSIONS!$I$3:$I$2094,N$1,MISSIONS!$A$3:$A$2094,Données!$A10)+ SUMIFS(MISSIONS!$D$3:$D$2094,MISSIONS!$I$3:$I$2094,N$1,MISSIONS!$C$3:$C$2094,Données!$A10) -> 0
A47: =Données!$A11 -> Acte | B47: =SUM(C47:N47) -> 0 | C47: =SUMIFS(MISSIONS!$B$3:$B$2094,MISSIONS!$I$3:$I$2094,C$1,MISSIONS!$A$3:$A$2094,Données!$A11)+ SUMIFS(MISSIONS!$D$3:$D$2094,MISSIONS!$I$3:$I$2094,C$1,MISSIONS!$C$3:$C$2094,Données!$A11) -> 0 | D47: =SUMIFS(MISSIONS!$B$3:$B$2094,MISSIONS!$I$3:$I$2094,D$1,MISSIONS!$A$3:$A$2094,Données!$A11)+ SUMIFS(MISSIONS!$D$3:$D$2094,MISSIONS!$I$3:$I$2094,D$1,MISSIONS!$C$3:$C$2094,Données!$A11) -> 0 | E47: =SUMIFS(MISSIONS!$B$3:$B$2094,MISSIONS!$I$3:$I$2094,E$1,MISSIONS!$A$3:$A$2094,Données!$A11)+ SUMIFS(MISSIONS!$D$3:$D$2094,MISSIONS!$I$3:$I$2094,E$1,MISSIONS!$C$3:$C$2094,Données!$A11) -> 0 | F47: =SUMIFS(MISSIONS!$B$3:$B$2094,MISSIONS!$I$3:$I$2094,F$1,MISSIONS!$A$3:$A$2094,Données!$A11)+ SUMIFS(MISSIONS!$D$3:$D$2094,MISSIONS!$I$3:$I$2094,F$1,MISSIONS!$C$3:$C$2094,Données!$A11) -> 0 | G47: =SUMIFS(MISSIONS!$B$3:$B$2094,MISSIONS!$I$3:$I$2094,G$1,MISSIONS!$A$3:$A$2094,Données!$A11)+ SUMIFS(MISSIONS!$D$3:$D$2094,MISSIONS!$I$3:$I$2094,G$1,MISSIONS!$C$3:$C$2094,Données!$A11) -> 0 | H47: =SUMIFS(MISSIONS!$B$3:$B$2094,MISSIONS!$I$3:$I$2094,H$1,MISSIONS!$A$3:$A$2094,Données!$A11)+ SUMIFS(MISSIONS!$D$3:$D$2094,MISSIONS!$I$3:$I$2094,H$1,MISSIONS!$C$3:$C$2094,Données!$A11) -> 0 | I47: =SUMIFS(MISSIONS!$B$3:$B$2094,MISSIONS!$I$3:$I$2094,I$1,MISSIONS!$A$3:$A$2094,Données!$A11)+ SUMIFS(MISSIONS!$D$3:$D$2094,MISSIONS!$I$3:$I$2094,I$1,MISSIONS!$C$3:$C$2094,Données!$A11) -> 0 | J47: =SUMIFS(MISSIONS!$B$3:$B$2094,MISSIONS!$I$3:$I$2094,J$1,MISSIONS!$A$3:$A$2094,Données!$A11)+ SUMIFS(MISSIONS!$D$3:$D$2094,MISSIONS!$I$3:$I$2094,J$1,MISSIONS!$C$3:$C$2094,Données!$A11) -> 0 | ... N47: =SUMIFS(MISSIONS!$B$3:$B$2094,MISSIONS!$I$3:$I$2094,N$1,MISSIONS!$A$3:$A$2094,Données!$A11)+ SUMIFS(MISSIONS!$D$3:$D$2094,MISSIONS!$I$3:$I$2094,N$1,MISSIONS!$C$3:$C$2094,Données!$A11) -> 0
...

Sheet MISSIONS
A2: Apport | B2: x | C2: Parr | D2: x | F2: =Données!E1 -> Client | H2: Mission | I2: Mois | L2: € | M2: €€ | N2: x | O2: Reste | P2: Agence | Q2: x | R2: Gestion | S2: Ml | T2: Lt | U2: Avant | V2: Apport | W2: x | Z2: Fred | AB2: Eric | AD2: Boom | AF2: Damien | AH2: Maitre | AJ2: x | AL2: x | AN2: x | AP2: x | AR2: x | AT2: x | AU2: Reliquat
B3: =IF(A3="",0,((U3)*10%)) -> 0 | I3: Janvier
I4: Janvier
A5: Colpa | D5: =IF(C5="",0,((U5)*5%)) -> 0 | F5: Adrian | G5: kdekom | H5: contrat Da | I5: Mars | J5: =L5 -> 500 | L5: 500 | M5: =L5 -> 500 | N5: 250 | O5: =M5-N5 -> 250 | T5: 250 | U5: =O5-P5-Q5-R5-S5-T5 -> 0 | V5: =U5-B5-D5 -> 0 | X5: =100%-Y5-AA5-AC5-AE5-AG5-AI5-AK5-AM5-AO5-AQ5 -> 1 | Z5: =(V5*Y5)+Q5+R5 -> 0 | AB5: =(V5*AA5) -> 0 | AF5: =V5*AE5 -> 0 | AH5: =V5*AG5 -> 0 | AJ5: =V5*AI5 -> 0 | AL5: =V5*AK5 -> 0 | AN5: =V5*AM5 -> 0 | AP5: =V5*AO5 -> 0 | AR5: =V5*AQ5 -> 0 | AT5: =X5*AS5 -> 0 | AU5: =V5*X5 -> 0
A6: Colpa | B6: =IF(A6="",0,((U6)*10%)) -> 44.64 | D6: =IF(C6="",0,((U6)*5%)) -> 0 | F6: Adrian | G6: kdekom | H6: Da 3 | I6: Mars | J6: =L6*2 -> 1550 | L6: 775 | M6: =L6 -> 775 | O6: =M6-N6 -> 775 | P6: =(M6-N6)*10% -> 77.5 | Q6: =(M6-N6)*10% -> 77.5 | R6: =(M6-N6-P6-Q6)*20% -> 124 | S6: =(M6-N6-P6-Q6-R6)*10% -> 49.6 | U6: =M6-N6-P6-Q6-R6-S6-T6 -> 446.4 | V6: =U6-B6-D6 -> 401.76 | X6: =100%-Y6-AA6-AC6-AE6-AG6-AI6-AK6-AM6-AO6-AQ6 -> 0.03 | Y6: =(97%-AA6-AC6-AE6-AG6-AI6-AK6-AM6-AO6-AQ6-AS6) -> 0.97 | Z6: =(V6*Y6)+Q6+R6 -> 591.2072 | AB6: =(V6*AA6) -> 0 | AF6: =V6*AE6 -> 0 | AH6: =V6*AG6 -> 0 | AJ6: =V6*AI6 -> 0 | AL6: =V6*AK6 -> 0 | AN6: =V6*AM6 -> 0 | AP6: =V6*AO6 -> 0 | AR6: =V6*AQ6 -> 0 | AT6: =V6*AS6 -> 0 | AU6: =V6*X6 -> 12.0528
A7: Colpa | B7: =IF(A7="",0,((U7)*10%)) -> 44.64 | D7: =IF(C7="",0,((U7)*5%)) -> 0 | F7: Adrian | G7: kdekom | H7: Da 4 | I7: Avril | J7: =L7*2 -> 1550 | L7: 775 | M7: =L7 -> 775 | O7: =M7-N7 -> 775 | P7: =(M7-N7)*10% -> 77.5 | Q7: =(M7-N7)*10% -> 77.5 | R7: =(M7-N7-P7-Q7)*20% -> 124 | S7: =(M7-N7-P7-Q7-R7)*10% -> 49.6 | U7: =M7-N7-P7-Q7-R7-S7-T7 -> 446.4 | V7: =U7-B7-D7 -> 401.76 | X7: =100%-Y7-AA7-AC7-AE7-AG7-AI7-AK7-AM7-AO7-AQ7 -> 0.03 | Y7: =(97%-AA7-AC7-AE7-AG7-AI7-AK7-AM7-AO7-AQ7) -> 0.97 | Z7: =(V7*Y7)+Q7+R7 -> 591.2072 | AB7: =(V7*AA7) -> 0 | AF7: =V7*AE7 -> 0 | AH7: =V7*AG7 -> 0 | AJ7: =V7*AI7 -> 0 | AL7: =V7*AK7 -> 0 | AN7: =V7*AM7 -> 0 | AP7: =V7*AO7 -> 0 | AR7: =V7*AQ7 -> 0 | AT7: =V7*AS7 -> 0 | AU7: =V7*X7 -> 12.0528
A8: Colpa | B8: =IF(A8="",0,((U8)*10%)) -> 44.64 | D8: =IF(C8="",0,((U8)*5%)) -> 0 | F8: Adrian | G8: kdekom | H8: Da 5 | I8: Mai | J8: =L8*2 -> 1550 | L8: 775 | M8: =L8 -> 775 | O8: =M8-N8 -> 775 | P8: =(M8-N8)*10% -> 77.5 | Q8: =(M8-N8)*10% -> 77.5 | R8: =(M8-N8-P8-Q8)*20% -> 124 | S8: =(M8-N8-P8-Q8-R8)*10% -> 49.6 | U8: =M8-N8-P8-Q8-R8-S8-T8 -> 446.4 | V8: =U8-B8-D8 -> 401.76 | X8: =100%-Y8-AA8-AC8-AE8-AG8-AI8-AK8-AM8-AO8-AQ8 -> 0.03 | Y8: =(97%-AA8-AC8-AE8-AG8-AI8-AK8-AM8-AO8-AQ8) -> 0.97 | Z8: =(V8*Y8)+Q8+R8 -> 591.2072 | AB8: =(V8*AA8) -> 0 | AF8: =V8*AE8 -> 0 | AH8: =V8*AG8 -> 0 | AJ8: =V8*AI8 -> 0 | AL8: =V8*AK8 -> 0 | AN8: =V8*AM8 -> 0 | AP8: =V8*AO8 -> 0 | AR8: =V8*AQ8 -> 0 | AT8: =X8*AS8 -> 0 | AU8: =V8*X8 -> 12.0528
A9: Colpa | B9: =IF(A9="",0,((U9)*10%)) -> 50.22 | D9: =IF(C9="",0,((U9)*5%)) -> 0 | F9: Adrian | G9: kdekom | H9: Da 6 | I9: Juin | J9: =L9*2 -> 1550 | L9: 775 | M9: =L9 -> 775 | O9: =M9-N9 -> 775 | P9: =(M9-N9)*10% -> 77.5 | R9: =(M9-N9-P9-Q9)*20% -> 139.5 | S9: =(M9-N9-P9-Q9-R9)*10% -> 55.8 | U9: =M9-N9-P9-Q9-R9-S9-T9 -> 502.2 | V9: =U9-B9-D9 -> 451.98 | X9: =100%-Y9-AA9-AC9-AE9-AG9-AI9-AK9-AM9-AO9-AQ9 -> 0.03 | Y9: =(97%-AA9-AC9-AE9-AG9-AI9-AK9-AM9-AO9-AQ9) -> 0.97 | Z9: =(V9*Y9)+Q9+R9 -> 577.9206 | AB9: =(V9*AA9) -> 0 | AF9: =V9*AE9 -> 0 | AH9: =V9*AG9 -> 0 | AJ9: =V9*AI9 -> 0 | AL9: =V9*AK9 -> 0 | AN9: =V9*AM9 -> 0 | AP9: =V9*AO9 -> 0 | AR9: =V9*AQ9 -> 0 | AT9: =X9*AS9 -> 0 | AU9: =V9*X9 -> 13.5594
A10: Colpa | B10: =IF(A10="",0,((U10)*10%)) -> 64.8675 | D10: =IF(C10="",0,((U10)*5%)) -> 0 | F10: Adrian | G10: kdekom | H10: Da 7 | I10: Juillet | J10: =L10*2 -> 1550 | L10: 775 | M10: =L10 -> 775 | N10: 0 | O10: =M10-N10 -> 775 | P10: =(M10-N10)*10% -> 77.5 | S10: =(M10-N10-P10-Q10-R10)*7% -> 48.825 | U10: =M10-N10-P10-Q10-R10-S10-T10 -> 648.675 | V10: =U10-B10-D10 -> 583.8075 | X10: =100%-Y10-AA10-AC10-AE10-AG10-AI10-AK10-AM10-AO10-AQ10 -> 0.03 | Y10: =(97%-AA10-AC10-AE10-AG10-AI10-AK10-AM10-AO10-AQ10) -> 0.97 | Z10: =(V10*Y10)+Q10+R10 -> 566.29327 | AB10: =(V10*AA10) -> 0 | AF10: =V10*AE10 -> 0 | AH10: =V10*AG10 -> 0 | AJ10: =V10*AI10 -> 0 | AL10: =V10*AK10 -> 0 | AN10: =V10*AM10 -> 0 | AP10: =V10*AO10 -> 0 | AR10: =V10*AQ10 -> 0 | AT10: =X10*AS10 -> 0 | AU10: =V10*X10 -> 17.514225
A11: Colpa | B11: =IF(A11="",0,((U11)*20%)) -> 129.735 | D11: =IF(C11="",0,((U11)*5%)) -> 0 | F11: Adrian | G11: kdekom | H11: Da 8 | I11: Août | J11: =L11*2 -> 1550 | L11: 775 | M11: =L11 -> 775 | N11: 0 | O11: =M11-N11 -> 775 | P11: =(M11-N11)*10% -> 77.5 | S11: =(M11-N11-P11-Q11-R11)*7% -> 48.825 | U11: =M11-N11-P11-Q11-R11-S11-T11 -> 648.675 | V11: =U11-B11-D11 -> 518.94 | X11: =100%-Y11-AA11-AC11-AE11-AG11-AI11-AK11-AM11-AO11-AQ11 -> 0.03 | Y11: =(97%-AA11-AC11-AE11-AG11-AI11-AK11-AM11-AO11-AQ11) -> 0.92 | Z11: =(V11*Y11)+Q11+R11 -> 477.4248 | AA11: 0.05 | AB11: =(V11*AA11) -> 25.947 | AF11: =V11*AE11 -> 0 | AH11: =V11*AG11 -> 0 | AJ11: =V11*AI11 -> 0 | AL11: =V11*AK11 -> 0 | AN11: =V11*AM11 -> 0 | AP11: =V11*AO11 -> 0 | AR11: =V11*AQ11 -> 0 | AT11: =X11*AS11 -> 0 | AU11: =V11*X11 -> 15.5682
A12: Colpa | B12: =IF(A12="",0,((U12)*20%)) -> 122.5275 | D12: =IF(C12="",0,((U12)*5%)) -> 0 | F12: Adrian | G12: kdekom | H12: Da 9 | I12: Septembre | J12: =L12*2 -> 1550 | L12: 775 | M12: =L12 -> 775 | O12: =M12-N12 -> 775 | P12: =(M12-N12)*15% -> 116.25 | S12: =(M12-N12-P12-Q12-R12)*7% -> 46.1125 | U12: =M12-N12-P12-Q12-R12-S12-T12 -> 612.6375 | V12: =U12-B12-D12 -> 490.11 | X12: =100%-Y12-AA12-AC12-AE12-AG12-AI12-AK12-AM12-AO12-AQ12 -> 0.03 | Y12: =(97%-AA12-AC12-AE12-AG12-AI12-AK12-AM12-AO12-AQ12) -> 0.92 | Z12: =(V12*Y12)+Q12+R12 -> 450.9012 | AA12: 0.05 | AB12: =(V12*AA12) -> 24.5055 | AF12: =V12*AE12 -> 0 | AH12: =V12*AG12 -> 0 | AJ12: =V12*AI12 -> 0 | AL12: =V12*AK12 -> 0 | AN12: =V12*AM12 -> 0 | AP12: =V12*AO12 -> 0 | AR12: =V12*AQ12 -> 0 | AT12: =X12*AS12 -> 0 | AU12: =V12*X12 -> 14.7033
A13: Colpa | B13: =IF(A13="",0,((O13)*20%)) -> 155 | D13: =IF(C13="",0,((O13)*5%)) -> 0 | F13: Adrian | G13: kdekom | H13: Da 10 | I13: Octobre | J13: =L13*2 -> 1550 | L13: 775 | M13: =L13 -> 775 | O13: =M13-N13 -> 775 | P13: =(M13-N13)*5% -> 38.75 | S13: =(O13-P13)*7% -> 51.5375 | U13: =M13-N13-P13-Q13-R13-S13-T13 -> 684.7125 | V13: =U13-B13-D13 -> 529.7125 | X13: =100%-Y13-AA13-AC13-AE13-AG13-AI13-AK13-AM13-AO13-AQ13 -> 0.01 | Y13: =(99%-AA13-AC13-AE13-AG13-AI13-AK13-AM13-AO13-AQ13) -> 0.78 | Z13: =(V13*Y13)+Q13+R13 -> 413.17575 | AA13: 0.15 | AB13: =(V13*AA13) -> 79.456875 | AC13: 0.06 | AD13: =V13*AC13 -> 31.78275 | AF13: =V13*AE13 -> 0 | AH13: =V13*AG13 -> 0 | AJ13: =V13*AI13 -> 0 | AL13: =V13*AK13 -> 0 | AN13: =V13*AM13 -> 0 | AP13: =V13*AO13 -> 0 | AR13: =V13*AQ13 -> 0 | AT13: =X13*AS13 -> 0 | AU13: =V13*X13 -> 5.297125
A14: Colpa | B14: =IF(A14="",0,((O14)*20%)) -> 0 | D14: =IF(C14="",0,((O14)*5%)) -> 0 | F14: Adrian | G14: kdekom | H14: Da 11 | I14: Novembre | J14: =L14*2 -> 1550 | L14: 775 | N14: 0 | O14: =M14-N14 -> 0 | P14: =(M14-N14)*5% -> 0 | S14: =(O14-P14)*7% -> 0 | U14: =M14-N14-P14-Q14-R14-S14-T14 -> 0 | V14: =U14-B14-D14 -> 0 | X14: =100%-Y14-AA14-AC14-AE14-AG14-AI14-AK14-AM14-AO14-AQ14 -> 0.01 | Y14: =(99%-AA14-AC14-AE14-AG14-AI14-AK14-AM14-AO14-AQ14) -> 0.78 | Z14: =(V14*Y14)+Q14+R14 -> 0 | AA14: 0.15 | AB14: =(V14*AA14) -> 0 | AC14: 0.06 | AD14: =V14*AC14 -> 0 | AF14: =V14*AE14 -> 0 | AH14: =V14*AG14 -> 0 | AJ14: =V14*AI14 -> 0 | AL14: =V14*AK14 -> 0 | AN14: =V14*AM14 -> 0 | AP14: =V14*AO14 -> 0 | AR14: =V14*AQ14 -> 0 | AT14: =X14*AS14 -> 0 | AU14: =V14*X14 -> 0
A15: Colpa | B15: =IF(A15="",0,((O15)*20%)) -> 0 | D15: =IF(C15="",0,((O15)*5%)) -> 0 | F15: Adrian | G15: kdekom | H15: Da 12 | I15: Décembre | J15: =L15*2 -> 1550 | L15: 775 | N15: 0 | O15: =M15-N15 -> 0 | P15: =(M15-N15)*5% -> 0 | S15: =(O15-P15)*7% -> 0 | U15: =M15-N15-P15-Q15-R15-S15-T15 -> 0 | V15: =U15-B15-D15 -> 0 | X15: =100%-Y15-AA15-AC15-AE15-AG15-AI15-AK15-AM15-AO15-AQ15 -> 0.01 | Y15: =(99%-AA15-AC15-AE15-AG15-AI15-AK15-AM15-AO15-AQ15) -> 0.78 | Z15: =(V15*Y15)+Q15+R15 -> 0 | AA15: 0.15 | AB15: =(V15*AA15) -> 0 | AC15: 0.06 | AD15: =V15*AC15 -> 0 | AF15: =V15*AE15 -> 0 | AH15: =V15*AG15 -> 0 | AJ15: =V15*AI15 -> 0 | AL15: =V15*AK15 -> 0 | AN15: =V15*AM15 -> 0 | AP15: =V15*AO15 -> 0 | AR15: =V15*AQ15 -> 0 | AT15: =X15*AS15 -> 0 | AU15: =V15*X15 -> 0
AC16: 0.06
B17: =IF(A17="",0,((U17)*10%)) -> 0 | D17: =IF(C17="",0,((U17)*5%)) -> 0 | F17: Argan | G17: kdekom | H17: Da 1 | I17: Janvier | J17: =L17*2 -> 630 | L17: 315 | M17: =L17 -> 315 | N17: 2 | O17: =M17-N17 -> 313 | P17: =(M17-N17)*10% -> 31.3 | Q17: =(M17-N17)*10% -> 31.3 | R17: =(M17-N17-P17-Q17)*20% -> 50.08 | U17: =M17-N17-P17-Q17-R17-S17 -> 200.32 | V17: =U17-B17-D17 -> 200.32 | X17: =100%-Y17-AA17-AC17-AE17-AG17-AI17-AK17-AM17-AO17-AQ17 -> 0.03 | Y17: =(97%-AA17-AC17-AE17-AG17-AI17-AK17-AM17-AO17-AQ17) -> 0.97 | Z17: =(V17*Y17)+Q17+R17 -> 275.6904 | AB17: =(V17*AA17) -> 0 | AF17: =V17*AE17 -> 0 | AH17: =V17*AG17 -> 0 | AJ17: =V17*AI17 -> 0 | AL17: =V17*AK17 -> 0 | AN17: =V17*AM17 -> 0 | AP17: =V17*AO17 -> 0 | AR17: =V17*AQ17 -> 0 | AT17: =X17*AS17 -> 0 | AU17: =V17*X17 -> 6.0096
B18: =IF(A18="",0,((U18)*10%)) -> 0 | D18: =IF(C18="",0,((U18)*5%)) -> 0 | F18: Argan | G18: kdekom | H18: Da 2 | I18: Février | J18: =L18*2 -> 630 | L18: 315 | M18: =L18 -> 315 | N18: 2 | O18: =M18-N18 -> 313 | P18: =(M18-N18)*10% -> 31.3 | Q18: =(M18-N18)*10% -> 31.3 | R18: =(M18-N18-P18-Q18)*20% -> 50.08 | U18: =M18-N18-P18-Q18-R18-S18 -> 200.32 | V18: =U18-B18-D18 -> 200.32 | X18: =100%-Y18-AA18-AC18-AE18-AG18-AI18-AK18-AM18-AO18-AQ18 -> 0.03 | Y18: =(97%-AA18-AC18-AE18-AG18-AI18-AK18-AM18-AO18-AQ18) -> 0.97 | Z18: =(V18*Y18)+Q18+R18 -> 275.6904 | AB18: =(V18*AA18) -> 0 | AF18: =V18*AE18 -> 0 | AH18: =V18*AG18 -> 0 | AJ18: =V18*AI18 -> 0 | AL18: =V18*AK18 -> 0 | AN18: =V18*AM18 -> 0 | AP18: =V18*AO18 -> 0 | AR18: =V18*AQ18 -> 0 | AT18: =X18*AS18 -> 0 | AU18: =V18*X18 -> 6.0096
B19: =IF(A19="",0,((U19)*10%)) -> 0 | D19: =IF(C19="",0,((U19)*5%)) -> 0 | F19: Argan | G19: kdekom | H19: Da 3 | I19: Mars | J19: =L19*2 -> 630 | L19: 315 | M19: =L19 -> 315 | N19: 2 | O19: =M19-N19 -> 313 | P19: =(M19-N19)*10% -> 31.3 | Q19: =(M19-N19)*10% -> 31.3 | R19: =(M19-N19-P19-Q19)*20% -> 50.08 | U19: =M19-N19-P19-Q19-R19-S19 -> 200.32 | V19: =U19-B19-D19 -> 200.32 | X19: =100%-Y19-AA19-AC19-AE19-AG19-AI19-AK19-AM19-AO19-AQ19 -> 0.03 | Y19: =(97%-AA19-AC19-AE19-AG19-AI19-AK19-AM19-AO19-AQ19) -> 0.97 | Z19: =(V19*Y19)+Q19+R19 -> 275.6904 | AB19: =(V19*AA19) -> 0 | AF19: =V19*AE19 -> 0 | AH19: =V19*AG19 -> 0 | AJ19: =V19*AI19 -> 0 | AL19: =V19*AK19 -> 0 | AN19: =V19*AM19 -> 0 | AP19: =V19*AO19 -> 0 | AR19: =V19*AQ19 -> 0 | AT19: =X19*AS19 -> 0 | AU19: =V19*X19 -> 6.0096
B20: =IF(A20="",0,((U20)*10%)) -> 0 | D20: =IF(C20="",0,((U20)*5%)) -> 0 | F20: Argan | G20: kdekom | H20: Da 4 | I20: Avril | J20: =L20*2 -> 630 | L20: 315 | M20: =L20 -> 315 | N20: 2 | O20: =M20-N20 -> 313 | P20: =(M20-N20)*10% -> 31.3 | Q20: =(M20-N20)*10% -> 31.3 | R20: =(M20-N20-P20-Q20)*20% -> 50.08 | U20: =M20-N20-P20-Q20-R20-S20 -> 200.32 | V20: =U20-B20-D20 -> 200.32 | X20: =100%-Y20-AA20-AC20-AE20-AG20-AI20-AK20-AM20-AO20-AQ20 -> 0.03 | Y20: =(97%-AA20-AC20-AE20-AG20-AI20-AK20-AM20-AO20-AQ20) -> 0.97 | Z20: =(V20*Y20)+Q20+R20 -> 275.6904 | AB20: =(V20*AA20) -> 0 | AF20: =V20*AE20 -> 0 | AH20: =V20*AG20 -> 0 | AJ20: =V20*AI20 -> 0 | AL20: =V20*AK20 -> 0 | AN20: =V20*AM20 -> 0 | AP20: =V20*AO20 -> 0 | AR20: =V20*AQ20 -> 0 | AT20: =X20*AS20 -> 0 | AU20: =V20*X20 -> 6.0096
B21: =IF(A21="",0,((U21)*10%)) -> 0 | D21: =IF(C21="",0,((U21)*5%)) -> 0 | F21: Argan | G21: kdekom | H21: Da 5 | I21: Mai | J21: =L21*2 -> 630 | L21: 315 | M21: =L21 -> 315 | N21: 2 | O21: =M21-N21 -> 313 | P21: =(M21-N21)*10% -> 31.3 | Q21: =(M21-N21)*10% -> 31.3 | R21: =(M21-N21-P21-Q21)*20% -> 50.08 | U21: =M21-N21-P21-Q21-R21-S21 -> 200.32 | V21: =U21-B21-D21 -> 200.32 | X21: =100%-Y21-AA21-AC21-AE21-AG21-AI21-AK21-AM21-AO21-AQ21 -> 0.03 | Y21: =(97%-AA21-AC21-AE21-AG21-AI21-AK21-AM21-AO21-AQ21) -> 0.97 | Z21: =(V21*Y21)+Q21+R21 -> 275.6904 | AB21: =(V21*AA21) -> 0 | AF21: =V21*AE21 -> 0 | AH21: =V21*AG21 -> 0 | AJ21: =V21*AI21 -> 0 | AL21: =V21*AK21 -> 0 | AN21: =V21*AM21 -> 0 | AP21: =V21*AO21 -> 0 | AR21: =V21*AQ21 -> 0 | AT21: =X21*AS21 -> 0 | AU21: =V21*X21 -> 6.0096
B22: =IF(A22="",0,((U22)*10%)) -> 0 | D22: =IF(C22="",0,((U22)*5%)) -> 0 | F22: Argan | G22: kdekom | H22: Da 6 | I22: Juin | J22: =L22*2 -> 630 | L22: 315 | M22: =L22 -> 315 | N22: 0 | O22: =M22-N22 -> 315 | P22: =(M22-N22)*10% -> 31.5 | Q22: =(M22-N22)*10% -> 31.5 | R22: =(M22-N22-P22-Q22)*20% -> 50.4 | U22: =M22-N22-P22-Q22-R22-S22 -> 201.6 | V22: =U22-B22-D22 -> 201.6 | X22: =100%-Y22-AA22-AC22-AE22-AG22-AI22-AK22-AM22-AO22-AQ22 -> 0.03 | Y22: =(97%-AA22-AC22-AE22-AG22-AI22-AK22-AM22-AO22-AQ22) -> 0.97 | Z22: =(V22*Y22)+Q22+R22 -> 277.452 | AB22: =(V22*AA22) -> 0 | AF22: =V22*AE22 -> 0 | AH22: =V22*AG22 -> 0 | AJ22: =V22*AI22 -> 0 | AL22: =V22*AK22 -> 0 | AN22: =V22*AM22 -> 0 | AP22: =V22*AO22 -> 0 | AR22: =V22*AQ22 -> 0 | AT22: =X22*AS22 -> 0 | AU22: =V22*X22 -> 6.048
B23: =IF(A23="",0,((U23)*10%)) -> 0 | D23: =IF(C23="",0,((U23)*5%)) -> 0 | F23: Argan | G23: kdekom | H23: Da 7 | I23: Juillet | J23: =L23*2 -> 630 | L23: 315 | M23: =L23 -> 315 | N23: 0 | O23: =M23-N23 -> 315 | P23: =(M23-N23)*10% -> 31.5 | R23: =(M23-N23-P23-Q23)*20% -> 56.7 | U23: =M23-N23-P23-Q23-R23-S23 -> 226.8 | V23: =U23-B23-D23 -> 226.8 | X23: =100%-Y23-AA23-AC23-AE23-AG23-AI23-AK23-AM23-AO23-AQ23 -> 0.03 | Y23: =(97%-AA23-AC23-AE23-AG23-AI23-AK23-AM23-AO23-AQ23) -> 0.97 | Z23: =(V23*Y23)+Q23+R23 -> 276.696 | AB23: =(V23*AA23) -> 0 | AF23: =V23*AE23 -> 0 | AH23: =V23*AG23 -> 0 | AJ23: =V23*AI23 -> 0 | AL23: =V23*AK23 -> 0 | AN23: =V23*AM23 -> 0 | AP23: =V23*AO23 -> 0 | AR23: =V23*AQ23 -> 0 | AT23: =X23*AS23 -> 0 | AU23: =V23*X23 -> 6.804
B24: =IF(A24="",0,((U24)*10%)) -> 0 | D24: =IF(C24="",0,((U24)*5%)) -> 0 | F24: Argan | G24: kdekom | H24: Da 8 | I24: Août | J24: =L24*2 -> 630 | L24: 315 | M24: =L24 -> 315 | N24: 0 | O24: =M24-N24 -> 315 | P24: =(M24-N24)*10% -> 31.5 | U24: =M24-N24-P24-Q24-R24-S24 -> 283.5 | V24: =U24-B24-D24 -> 283.5 | X24: =100%-Y24-AA24-AC24-AE24-AG24-AI24-AK24-AM24-AO24-AQ24 -> 0.03 | Y24: =(97%-AA24-AC24-AE24-AG24-AI24-AK24-AM24-AO24-AQ24) -> 0.92 | Z24: =(V24*Y24)+Q24+R24 -> 260.82 | AA24: 0.05 | AB24: =(V24*AA24) -> 14.175 | AF24: =V24*AE24 -> 0 | AH24: =V24*AG24 -> 0 | AJ24: =V24*AI24 -> 0 | AL24: =V24*AK24 -> 0 | AN24: =V24*AM24 -> 0 | AP24: =V24*AO24 -> 0 | AR24: =V24*AQ24 -> 0 | AT24: =X24*AS24 -> 0 | AU24: =V24*X24 -> 8.505
B25: =IF(A25="",0,((U25)*10%)) -> 0 | D25: =IF(C25="",0,((U25)*5%)) -> 0 | F25: Argan | G25: kdekom | H25: Da 9 | I25: Septembre | J25: =L25*2 -> 630 | L25: 315 | M25: =L25 -> 315 | O25: =M25-N25 -> 315 | P25: =(M25-N25)*15% -> 47.25 | U25: =M25-N25-P25-Q25-R25-S25 -> 267.75 | V25: =U25-B25-D25 -> 267.75 | X25: =100%-Y25-AA25-AC25-AE25-AG25-AI25-AK25-AM25-AO25-AQ25 -> 0.03 | Y25: =(97%-AA25-AC25-AE25-AG25-AI25-AK25-AM25-AO25-AQ25) -> 0.92 | Z25: =(V25*Y25)+Q25+R25 -> 246.33 | AA25: 0.05 | AB25: =(V25*AA25) -> 13.3875 | AF25: =V25*AE25 -> 0 | AH25: =V25*AG25 -> 0 | AJ25: =V25*AI25 -> 0 | AL25: =V25*AK25 -> 0 | AN25: =V25*AM25 -> 0 | AP25: =V25*AO25 -> 0 | AR25: =V25*AQ25 -> 0 | AT25: =X25*AS25 -> 0 | AU25: =V25*X25 -> 8.0325
F26: Argan | G26: kdekom | H26: Da 10 | I26: Octobre | J26: =L26*2 -> 630 | L26: 315 | M26: =L26 -> 315 | O26: =M26-N26 -> 315 | P26: =(M26-N26)*5% -> 15.75 | S26: =(O26-P26)*7% -> 20.9475 | U26: =M26-N26-P26-Q26-R26-S26 -> 278.3025 | V26: =U26-B26-D26 -> 278.3025 | X26: =100%-Y26-AA26-AC26-AE26-AG26-AI26-AK26-AM26-AO26-AQ26 -> 0.01 | Y26: =(99%-AA26-AC26-AE26-AG26-AI26-AK26-AM26-AO26-AQ26) -> 0.78 | Z26: =(V26*Y26)+Q26+R26 -> 217.07595 | AA26: 0.15 | AB26: =(V26*AA26) -> 41.745375 | AC26: 0.06 | AD26: =V26*AC26 -> 16.69815 | AF26: =V26*AE26 -> 0 | AH26: =V26*AG26 -> 0 | AJ26: =V26*AI26 -> 0 | AL26: =V26*AK26 -> 0 | AN26: =V26*AM26 -> 0 | AP26: =V26*AO26 -> 0 | AR26: =V26*AQ26 -> 0 | AT26: =X26*AS26 -> 0 | AU26: =V26*X26 -> 2.783025
B27: =IF(A27="",0,((U27)*10%)) -> 0 | D27: =IF(C27="",0,((U27)*5%)) -> 0 | F27: Argan | G27: kdekom | H27: Da 11 | I27: Novembre | J27: =L27*2 -> 630 | L27: 315 | N27: 0 | O27: =M27-N27 -> 0 | P27: =(M27-N27)*5% -> 0 | S27: =(O27-P27)*7% -> 0 | U27: =M27-N27-P27-Q27-R27-S27 -> 0 | V27: =U27-B27-D27 -> 0 | X27: =100%-Y27-AA27-AC27-AE27-AG27-AI27-AK27-AM27-AO27-AQ27 -> 0.01 | Y27: =(99%-AA27-AC27-AE27-AG27-AI27-AK27-AM27-AO27-AQ27) -> 0.78 | Z27: =(V27*Y27)+Q27+R27 -> 0 | AA27: 0.15 | AB27: =(V27*AA27) -> 0 | AC27: 0.06 | AD27: =V27*AC27 -> 0 | AF27: =V27*AE27 -> 0 | AH27: =V27*AG27 -> 0 | AJ27: =V27*AI27 -> 0 | AL27: =V27*AK27 -> 0 | AN27: =V27*AM27 -> 0 | AP27: =V27*AO27 -> 0 | AR27: =V27*AQ27 -> 0 | AT27: =X27*AS27 -> 0 | AU27: =V27*X27 -> 0
B28: =IF(A28="",0,((U28)*10%)) -> 0 | D28: =IF(C28="",0,((U28)*5%)) -> 0 | F28: Argan | G28: kdekom | H28: Da 12 | I28: Décembre | J28: =L28*2 -> 630 | L28: 315 | N28: 0 | O28: =M28-N28 -> 0 | P28: =(M28-N28)*5% -> 0 | S28: =(O28-P28)*7% -> 0 | U28: =M28-N28-P28-Q28-R28-S28 -> 0 | V28: =U28-B28-D28 -> 0 | X28: =100%-Y28-AA28-AC28-AE28-AG28-AI28-AK28-AM28-AO28-AQ28 -> 0.01 | Y28: =(99%-AA28-AC28-AE28-AG28-AI28-AK28-AM28-AO28-AQ28) -> 0.78 | Z28: =(V28*Y28)+Q28+R28 -> 0 | AA28: 0.15 | AB28: =(V28*AA28) -> 0 | AC28: 0.06 | AD28: =V28*AC28 -> 0 | AF28: =V28*AE28 -> 0 | AH28: =V28*AG28 -> 0 | AJ28: =V28*AI28 -> 0 | AL28: =V28*AK28 -> 0 | AN28: =V28*AM28 -> 0 | AP28: =V28*AO28 -> 0 | AR28: =V28*AQ28 -> 0 | AT28: =X28*AS28 -> 0 | AU28: =V28*X28 -> 0
A30: Donovan | B30: =IF(A30="",0,((U30)*10%)) -> 33.80736 | D30: =IF(C30="",0,((U30)*5%)) -> 0 | F30: Aupus | G30: kdekom | H30: Da 1 | I30: Janvier | J30: =L30*2 -> 1136 | L30: 568 | M30: =L30 -> 568 | O30: =M30-N30 -> 568 | P30: =(M30-N30)*10% -> 56.8 | Q30: =(M30-N30)*10% -> 56.8 | R30: =(M30-N30-P30-Q30)*20% -> 90.88 | S30: =(O30-P30-Q30-R30)*7% -> 25.4464 | U30: =M30-N30-P30-Q30-R30-S30 -> 338.0736 | V30: =U30-B30-D30 -> 304.26624 | X30: =100%-Y30-AA30-AC30-AE30-AG30-AI30-AK30-AM30-AO30-AQ30 -> 0.03 | Y30: =(97%-AA30-AC30-AE30-AG30-AI30-AK30-AM30-AO30-AQ30) -> 0.97 | Z30: =(V30*Y30)+Q30+R30 -> 442.81825 | AB30: =(V30*AA30) -> 0 | AF30: =V30*AE30 -> 0 | AH30: =V30*AG30 -> 0 | AJ30: =V30*AI30 -> 0 | AL30: =V30*AK30 -> 0 | AN30: =V30*AM30 -> 0 | AP30: =V30*AO30 -> 0 | AR30: =V30*AQ30 -> 0 | AT30: =X30*AS30 -> 0 | AU30: =V30*X30 -> 9.1279872
A31: Donovan | B31: =IF(A31="",0,((U31)*10%)) -> 33.80736 | D31: =IF(C31="",0,((U31)*5%)) -> 0 | F31: Aupus | G31: kdekom | H31: Da 2 | I31: Février | J31: =L31*2 -> 1136 | L31: 568 | M31: =L31 -> 568 | N31: 0 | O31: =M31-N31 -> 568 | P31: =(M31-N31)*10% -> 56.8 | Q31: =(M31-N31)*10% -> 56.8 | R31: =(M31-N31-P31-Q31)*20% -> 90.88 | S31: =(O31-P31-Q31-R31)*7% -> 25.4464 | U31: =M31-N31-P31-Q31-R31-S31 -> 338.0736 | V31: =U31-B31-D31 -> 304.26624 | X31: =100%-Y31-AA31-AC31-AE31-AG31-AI31-AK31-AM31-AO31-AQ31 -> 0.03 | Y31: =(97%-AA31-AC31-AE31-AG31-AI31-AK31-AM31-AO31-AQ31) -> 0.97 | Z31: =(V31*Y31)+Q31+R31 -> 442.81825 | AB31: =(V31*AA31) -> 0 | AF31: =V31*AE31 -> 0 | AH31: =V31*AG31 -> 0 | AJ31: =V31*AI31 -> 0 | AL31: =V31*AK31 -> 0 | AN31: =V31*AM31 -> 0 | AP31: =V31*AO31 -> 0 | AR31: =V31*AQ31 -> 0 | AT31: =X31*AS31 -> 0 | AU31: =V31*X31 -> 9.1279872
A32: Donovan | B32: =IF(A32="",0,((U32)*10%)) -> 33.80736 | D32: =IF(C32="",0,((U32)*5%)) -> 0 | F32: Aupus | G32: kdekom | H32: Da 3 | I32: Mars | J32: =L32*2 -> 1136 | L32: 568 | M32: =L32 -> 568 | N32: 0 | O32: =M32-N32 -> 568 | P32: =(M32-N32)*10% -> 56.8 | Q32: =(M32-N32)*10% -> 56.8 | R32: =(M32-N32-P32-Q32)*20% -> 90.88 | S32: =(O32-P32-Q32-R32)*7% -> 25.4464 | U32: =M32-N32-P32-Q32-R32-S32 -> 338.0736 | V32: =U32-B32-D32 -> 304.26624 | X32: =100%-Y32-AA32-AC32-AE32-AG32-AI32-AK32-AM32-AO32-AQ32 -> 0.03 | Y32: =(97%-AA32-AC32-AE32-AG32-AI32-AK32-AM32-AO32-AQ32) -> 0.97 | Z32: =(V32*Y32)+Q32+R32 -> 442.81825 | AB32: =(V32*AA32) -> 0 | AF32: =V32*AE32 -> 0 | AH32: =V32*AG32 -> 0 | AJ32: =V32*AI32 -> 0 | AL32: =V32*AK32 -> 0 | AN32: =V32*AM32 -> 0 | AP32: =V32*AO32 -> 0 | AR32: =V32*AQ32 -> 0 | AT32: =X32*AS32 -> 0 | AU32: =V32*X32 -> 9.1279872
A33: Donovan | B33: =IF(A33="",0,((U33)*10%)) -> 33.80736 | D33: =IF(C33="",0,((U33)*5%)) -> 0 | F33: Aupus | G33: kdekom | H33: Da 4 | I33: Mai | J33: =L33*2 -> 1136 | L33: 568 | M33: =L33 -> 568 | N33: 0 | O33: =M33-N33 -> 568 | P33: =(M33-N33)*10% -> 56.8 | Q33: =(M33-N33)*10% -> 56.8 | R33: =(M33-N33-P33-Q33)*20% -> 90.88 | S33: =(O33-P33-Q33-R33)*7% -> 25.4464 | U33: =M33-N33-P33-Q33-R33-S33 -> 338.0736 | V33: =U33-B33-D33 -> 304.26624 | X33: =100%-Y33-AA33-AC33-AE33-AG33-AI33-AK33-AM33-AO33-AQ33 -> 0.03 | Y33: =(97%-AA33-AC33-AE33-AG33-AI33-AK33-AM33-AO33-AQ33) -> 0.97 | Z33: =(V33*Y33)+Q33+R33 -> 442.81825 | AB33: =(V33*AA33) -> 0 | AF33: =V33*AE33 -> 0 | AH33: =V33*AG33 -> 0 | AJ33: =V33*AI33 -> 0 | AL33: =V33*AK33 -> 0 | AN33: =V33*AM33 -> 0 | AP33: =V33*AO33 -> 0 | AR33: =V33*AQ33 -> 0 | AT33: =X33*AS33 -> 0 | AU33: =V33*X33 -> 9.1279872
A34: Donovan | B34: =IF(A34="",0,((U34)*10%)) -> 33.80736 | D34: =IF(C34="",0,((U34)*5%)) -> 0 | F34: Aupus | G34: kdekom | H34: Da 5 | I34: Mai | J34: =L34*2 -> 1136 | L34: 568 | M34: =L34 -> 568 | O34: =M34-N34 -> 568 | P34: =(M34-N34)*10% -> 56.8 | Q34: =(M34-N34)*10% -> 56.8 | R34: =(M34-N34-P34-Q34)*20% -> 90.88 | S34: =(O34-P34-Q34-R34)*7% -> 25.4464 | U34: =M34-N34-P34-Q34-R34-S34 -> 338.0736 | V34: =U34-B34-D34 -> 304.26624 | X34: =100%-Y34-AA34-AC34-AE34-AG34-AI34-AK34-AM34-AO34-AQ34 -> 0.03 | Y34: =(97%-AA34-AC34-AE34-AG34-AI34-AK34-AM34-AO34-AQ34) -> 0.97 | Z34: =(V34*Y34)+Q34+R34 -> 442.81825 | AB34: =(V34*AA34) -> 0 | AF34: =V34*AE34 -> 0 | AH34: =V34*AG34 -> 0 | AJ34: =V34*AI34 -> 0 | AL34: =V34*AK34 -> 0 | AN34: =V34*AM34 -> 0 | AP34: =V34*AO34 -> 0 | AR34: =V34*AQ34 -> 0 | AT34: =X34*AS34 -> 0 | AU34: =V34*X34 -> 9.1279872
B35: =IF(A35="",0,((U35)*10%)) -> 0 | D35: =IF(C35="",0,((U35)*5%)) -> 0 | F35: Aupus | G35: kdekom | H35: Da 6 | I35: Juillet | J35: =L35*2 -> 1136 | L35: 568 | M35: =L35 -> 568 | N35: 0 | O35: =M35-N35 -> 568 | P35: =(M35-N35)*10% -> 56.8 | Q35: =(M35-N35)*10% -> 56.8 | R35: =(M35-N35-P35-Q35)*20% -> 90.88 | S35: =(O35-P35-Q35-R35)*7% -> 25.4464 | U35: =M35-N35-P35-Q35-R35-S35 -> 338.0736 | V35: =U35-B35-D35 -> 338.0736 | X35: =100%-Y35-AA35-AC35-AE35-AG35-AI35-AK35-AM35-AO35-AQ35 -> 0.03 | Y35: =(97%-AA35-AC35-AE35-AG35-AI35-AK35-AM35-AO35-AQ35) -> 0.97 | Z35: =(V35*Y35)+Q35+R35 -> 475.61139 | AB35: =(V35*AA35) -> 0 | AF35: =V35*AE35 -> 0 | AH35: =V35*AG35 -> 0 | AJ35: =V35*AI35 -> 0 | AL35: =V35*AK35 -> 0 | AN35: =V35*AM35 -> 0 | AP35: =V35*AO35 -> 0 | AR35: =V35*AQ35 -> 0 | AT35: =X35*AS35 -> 0 | AU35: =V35*X35 -> 10.142208
B36: =IF(A36="",0,((U36)*10%)) -> 0 | D36: =IF(C36="",0,((U36)*5%)) -> 0 | F36: Aupus | G36: kdekom | H36: Da 7 | I36: Juillet | J36: =L36*2 -> 1136 | L36: 568 | M36: =L36 -> 568 | N36: 0 | O36: =M36-N36 -> 568 | P36: =(M36-N36)*10% -> 56.8 | R36: =(M36-N36-P36-Q36)*20% -> 102.24 | S36: =(O36-P36-Q36-R36)*7% -> 28.6272 | U36: =M36-N36-P36-Q36-R36-S36 -> 380.3328 | V36: =U36-B36-D36 -> 380.3328 | X36: =100%-Y36-AA36-AC36-AE36-AG36-AI36-AK36-AM36-AO36-AQ36 -> 0.03 | Y36: =(97%-AA36-AC36-AE36-AG36-AI36-AK36-AM36-AO36-AQ36) -> 0.97 | Z36: =(V36*Y36)+Q36+R36 -> 471.16282 | AB36: =(V36*AA36) -> 0 | AF36: =V36*AE36 -> 0 | AH36: =V36*AG36 -> 0 | AJ36: =V36*AI36 -> 0 | AL36: =V36*AK36 -> 0 | AN36: =V36*AM36 -> 0 | AP36: =V36*AO36 -> 0 | AR36: =V36*AQ36 -> 0 | AT36: =X36*AS36 -> 0 | AU36: =V36*X36 -> 11.409984
B37: =IF(A37="",0,((U37)*10%)) -> 0 | D37: =IF(C37="",0,((U37)*5%)) -> 0 | F37: Aupus | G37: kdekom | H37: Da 8 | I37: Août | J37: =L37*2 -> 1136 | L37: 568 | M37: =L37 -> 568 | N37: 0 | O37: =M37-N37 -> 568 | P37: =(M37-N37)*10% -> 56.8 | S37: =(O37-P37-Q37-R37)*7% -> 35.784 | U37: =M37-N37-P37-Q37-R37-S37 -> 475.416 | V37: =U37-B37-D37 -> 475.416 | X37: =100%-Y37-AA37-AC37-AE37-AG37-AI37-AK37-AM37-AO37-AQ37 -> 0.03 | Y37: =(97%-AA37-AC37-AE37-AG37-AI37-AK37-AM37-AO37-AQ37) -> 0.92 | Z37: =(V37*Y37)+Q37+R37 -> 437.38272 | AA37: 0.05 | AB37: =(V37*AA37) -> 23.7708 | AF37: =V37*AE37 -> 0 | AH37: =V37*AG37 -> 0 | AJ37: =V37*AI37 -> 0 | AL37: =V37*AK37 -> 0 | AN37: =V37*AM37 -> 0 | AP37: =V37*AO37 -> 0 | AR37: =V37*AQ37 -> 0 | AT37: =X37*AS37 -> 0 | AU37: =V37*X37 -> 14.26248
B38: =IF(A38="",0,((U38)*10%)) -> 0 | D38: =IF(C38="",0,((U38)*5%)) -> 0 | F38: Aupus | G38: kdekom | H38: Da 9 | I38: Septembre | J38: =L38*2 -> 1136 | L38: 568 | M38: =L38 -> 568 | O38: =M38-N38 -> 568 | P38: =(M38-N38)*15% -> 85.2 | S38: =(O38-P38-Q38-R38)*7% -> 33.796 | U38: =M38-N38-P38-Q38-R38-S38 -> 449.004 | V38: =U38-B38-D38 -> 449.004 | X38: =100%-Y38-AA38-AC38-AE38-AG38-AI38-AK38-AM38-AO38-AQ38 -> 0.03 | Y38: =(97%-AA38-AC38-AE38-AG38-AI38-AK38-AM38-AO38-AQ38) -> 0.92 | Z38: =(V38*Y38)+Q38+R38 -> 413.08368 | AA38: 0.05 | AB38: =(V38*AA38) -> 22.4502 | AF38: =V38*AE38 -> 0 | AH38: =V38*AG38 -> 0 | AJ38: =V38*AI38 -> 0 | AL38: =V38*AK38 -> 0 | AN38: =V38*AM38 -> 0 | AP38: =V38*AO38 -> 0 | AR38: =V38*AQ38 -> 0 | AT38: =X38*AS38 -> 0 | AU38: =V38*X38 -> 13.47012
F39: Aupus | G39: kdekom | H39: Da 10 | I39: Octobre | J39: =L39*2 -> 1136 | L39: 568 | O39: =M39-N39 -> 0 | P39: =(M39-N39)*5% -> 0 | S39: =(O39-P39)*7% -> 0 | U39: =M39-N39-P39-Q39-R39-S39 -> 0 | V39: =U39-B39-D39 -> 0 | X39: =100%-Y39-AA39-AC39-AE39-AG39-AI39-AK39-AM39-AO39-AQ39 -> 0.01 | Y39: =(99%-AA39-AC39-AE39-AG39-AI39-AK39-AM39-AO39-AQ39) -> 0.78 | Z39: =(V39*Y39)+Q39+R39 -> 0 | AA39: 0.15 | AB39: =(V39*AA39) -> 0 | AC39: 0.06 | AD39: =V39*AC39 -> 0 | AF39: =V39*AE39 -> 0 | AH39: =V39*AG39 -> 0 | AJ39: =V39*AI39 -> 0 | AL39: =V39*AK39 -> 0 | AN39: =V39*AM39 -> 0 | AP39: =V39*AO39 -> 0 | AR39: =V39*AQ39 -> 0 | AT39: =X39*AS39 -> 0 | AU39: =V39*X39 -> 0
